Workbook

Sheet Siltuma aprēķins
T1: 19.5 | U1: 12
F2: 3.78 | T2: 0.05 | U2: 0.07
A3: 0.32 | B3: =B5*A3/A5 -> 5.5363322 | D3: Ūdens tarifs | E3: =Rekvizīti!C23 -> 3.2307 | U3: =E23 -> 6.7683034 | V3: 3.560928
A4: 5.46 | B4: =B5*A4/A5 -> 94.463668 | D4: Dzīvokļu/telpgrupu skaits | E4: 19.5 | I4: =(I16*L19)+H23+(G45*P19) -> 799.93794 | N4: apkure | O4: A.ūd. | P4: Vk.ūd.patēr. | R4: =ROUND(E23,2) -> 6.77 | U4: Cirk.
A5: =A3+A4 -> 5.78 | B5: 100 | D5: Koeficients (C) | E5: 0.0728 | F5: tarifs | G5: PVN
D6: Tarifs (ar PVN) (T) | E6: =F6+G6 -> 92.9712 | F6: 83.01 | G6: =ROUND(F6/100*12,4) -> 9.9612 | H6: =ROUND(F6/100*21,4) -> 17.4321 | I6: =F6+H6 -> 100.4421
D7: RS rēķina kopsumma EUR | E7: =(E8*F8)+(E9*F9) -> 729.3078 | F7: 83.01 | J7: 1 | K7: Veikals | L7: 41.9 | N7: =L7*$I$16 -> 26.767876 | O7: =Ūdens!F3 -> 1.22 | P7: =Ūdens!G3 -> 0.2 | R7: =J7*$R$4 -> 6.77 | U7: =J7*$U$3 -> 6.7683034 | V7: =$V$3 -> 3.560928
D8: veikali | E8: =F7+G8 -> 100.44 | F8: 0.43 | G8: =ROUND(F7/100*21,2) -> 17.43 | H8: =ROUND(E8*F8,2) -> 43.19 | J8: 1 | K8: Cafe | L8: 13.9 | N8: =L8*$I$16 -> 8.8800353 | O8: =Ūdens!F2 -> 2.4 | P8: =Ūdens!G2 -> 0.19 | R8: =J8*$R$4 -> 6.77 | U8: =J8*$U$3 -> 6.7683034 | V8: =$V$3 -> 3.560928
D9: dzīvokļi | E9: =F7+G9 -> 92.97 | F9: 7.38 | G9: =ROUND(F7/100*12,2) -> 9.96 | H9: =ROUND(E9*F9,2) -> 686.12 | J9: 2.5 | K9: Dzīvoklis Nr.3 - L.Loeve | L9: 111.04 | N9: =L9*$I$16 -> 70.938066 | O9: =Ūdens!F4 -> 0.57 | P9: =Ūdens!G4 -> 0.14 | R9: =J9*$R$4 -> 16.925 | U9: =J9*$U$3 -> 16.920758 | V9: =$V$3 -> 3.560928 | W9: =U7+U8+U9 -> 30.457365 | X9: =V7+V8+V9 -> 10.682784
A10: c - ūdens siltumietilpība c = 1; | E10: 1 | J10: 2.5 | K10: Dzīvoklis Nr.4 Hedija | L10: 109.4 | N10: =L10*$I$16 -> 69.89035 | O10: =Ūdens!F5 -> 3.79 | P10: =Ūdens!G5 -> 2.65 | R10: =J10*$R$4 -> 16.925 | U10: =J10*$U$3 -> 16.920758 | V10: =$V$3 -> 3.560928
A11: k 1 - siltuma zudumi ar starojumu no siltummaiņa apkārtējā telpā plākšņu tipa siltummainim k = 1,0; | E11: 1 | J11: 1 | K11: Dzīvoklis Nr.6 Ilze | L11: 28.4 | N11: =L11*$I$16 -> 18.143382 | O11: =Ūdens!F6 -> 0.05 | P11: =Ūdens!G6 -> 0.04 | R11: =J11*$R$4 -> 6.77 | U11: =J11*$U$3 -> 6.7683034 | V11: =$V$3 -> 3.560928
A12: k 2 - koeficients gigakalorijas [Gkal] pārveidošanai megavatstundā [MWh] - 0,8598 | E12: 0.8598 | F12: =POWER(10,3)*E12 -> 859.8 | J12: 2 | K12: Dzīvoklis Nr.7 Kristīne Meirāne | L12: 84.7 | N12: =L12*$I$16 -> 54.110719 | O12: =Ūdens!F7 -> 5.57 | P12: =Ūdens!G7 -> 3.41 | R12: =J12*$R$4 -> 13.54 | U12: =J12*$U$3 -> 13.536607 | V12: =$V$3 -> 3.560928
J13: 1 | K13: Dzīvoklis Nr.8 Anastasija | L13: 47.8 | N13: =L13*$I$16 -> 30.5371 | O13: =Ūdens!F8 -> 6.68 | P13: =Ūdens!G8 -> 3.87 | R13: =J13*$R$4 -> 6.77 | U13: =J13*$U$3 -> 6.7683034 | V13: =$V$3 -> 3.560928
D14: aukstā ūdens patēriņš | E14: 56.31 | J14: 2 | K14: Dzīvoklis Nr.9 Sanita&Rihards | L14: 65.7 | N14: =L14*$I$16 -> 41.972541 | O14: =Ūdens!F9 -> 0 | P14: =Ūdens!G9 -> 0 | R14: =J14*$R$4 -> 13.54 | U14: =J14*$U$3 -> 13.536607 | V14: =$V$3 -> 3.560928
D15: RS patēriņš (Qpieg.) | E15: 7.81 | G15: =ROUND(E7,2) -> 729.31 | I15: apk./kvm | J15: 1 | K15: Dzīvoklis Nr.10 Roberts&Anna | L15: 47.1 | N15: =L15*$I$16 -> 30.089904 | O15: =Ūdens!F10 -> 3.15 | P15: =Ūdens!G10 -> 3.57 | R15: =J15*$R$4 -> 6.77 | U15: =J15*$U$3 -> 6.7683034 | V15: =$V$3 -> 3.560928
D16: Apkure (Qapk.) ziemā | E16: =ROUND(E15-E26-F34,4) -> 5.3716 | F16: =ROUND(E15-(E26+E33),4) -> 5.3716 | G16: =ROUND(E7-G18-(E23*E4),2) -> 502.61 | H16: =ROUND(E16*E6,2) -> 499.4 | I16: =G16/L19 -> 0.63885146 | J16: 2 | K16: Dzīvoklis Nr.11 Rūdolfs&Marta | L16: 64.4 | N16: =L16*$I$16 -> 41.142034 | O16: =Ūdens!F11 -> 8.08 | P16: =Ūdens!G11 -> 5.82 | R16: =J16*$R$4 -> 13.54 | U16: =J16*$U$3 -> 13.536607 | V16: =$V$3 -> 3.560928
D17: Apkure (Qapk.) vasarā | E17: 0 | I17: =(H23+G16)/L19 -> 0.80660945 | J17: 2.5 | K17: Dzīvoklis Nr.12 Santa&Valters | L17: 93.7 | M17: 99.1 | N17: =L17*$I$16 -> 59.860382 | O17: =Ūdens!F12 -> 5.66 | P17: =Ūdens!G12 -> 2.09 | R17: =J17*$R$4 -> 16.925 | U17: =J17*$U$3 -> 16.920758 | V17: =$V$3 -> 3.560928
D18: K.ūd.skaitītāja patēriņš (Va.ūd.smn.) | E18: 21.9 | G18: =G34 -> 94.72 | H18: =ROUND(G18/E18,2) -> 4.33 | J18: 1 | K18: Pagrabs | L18: 78.7 | N18: =L18*$I$16 -> 50.27761 | O18: =Ūdens!F13 -> 0 | P18: =Ūdens!G13 -> 0.07 | R18: =J18*$R$4 -> 6.77 | U18: =J18*$U$3 -> 6.7683034 | V18: =$V$3 -> 3.560928
D19: t⁰k.ūd. | E19: 55 | H19: bez pvn 12% | I19: =I16-(I16/100*12) -> 0.56218929 | L19: =SUM(L7:L18) -> 786.74 | N19: =L19*$I$16 -> 502.61 | O19: =Ūdens!F14 -> 34.77 | P19: =Ūdens!G14 -> 21.86 | Q19: =Ūdens!H14
D20: t⁰a.ūd. | E20: 15 | G20: =G16+G18+H23 -> 729.31192 | H20: veikali apk. Ar pvn | I20: =I19+(I19/100*21) -> 0.68024904 | J20: =SUM(J6:J19) -> 19.5 | U20: =SUM(U7:U19) -> 131.98192 | V20: =SUM(V7:V19) -> 42.731136
H21: dzīvokļi apk. | I21: =I19+(I19/100*12) -> 0.629652
D22: Apkurei Q | E22: =E15-E33-E31 -> 5.3715584 | K22: Pagrabs 1/3 | N22: =N18/3 -> 16.759203
D23: Maksa par cirkulāciju (Mk.ūd.cirk.) | E23: =E5*E6 -> 6.7683034 | H23: =E23*E4 -> 131.98192 | K23: =L18/3 -> 26.233333 | U23: 2.66 | V23: 3.39
E25: SE
D26: Cirkulācija (Qcirk.) | E26: =E4*E5 -> 1.4196 | M26: difer. | N26: izlīdz.
B27: Vasaras periodā | D27: RS kopējais daudzums k.ūd. (Qk.ūd.(vas.sez.)) | E27: =E15-E26 -> 6.3904 | I27: k.ūd. kubs | L27: cirk(3) | M27: =U10 -> 16.920758 | N27: =V10 -> 3.560928
D28: Viena m3 uzsildīšana karstajam ūd. (qk.ūd.(vas.sez.)) | E28: =E27/E18 -> 0.29179909 | F28: =E15-E26-E17 -> 6.3904 | G28: =ROUND(F28*E6,2) -> 594.12 | I28: =ROUND(G28/E18,2)+E3 -> 30.3607 | L28: x2 kubi | M28: =$U$23*2 -> 5.32 | N28: =$V$23*2 -> 6.78
D29: Patērētās siltumenerģijas daudzums (Qptr.) | E29: =E26+E27+E17 -> 7.81 | L29: kopā | M29: =M27+M28 -> 22.240758 | N29: =N27+N28 -> 10.340928 | P29: =N29-M29 -> -11.89983
D31: Cirkulācija (Qcirk.) | E31: =E4*E5 -> 1.4196 | L31: cirk(1) | M31: =U11 -> 6.7683034 | N31: =V14 -> 3.560928
B32: Ziemas periodā | D32: Patērētās siltumenerģijas daudzums (Qptr.) | E32: =E26+E33+E16 -> 7.8100416 | L32: x2 kubi | M32: =$U$23*2 -> 5.32 | N32: =$V$23*2 -> 6.78
D33: RS daudzums k.ūd. (Qk.ūd.(apk.sez.)) | E33: =E34*E18 -> 1.0188416 | I33: k.ūd. kubs | L33: kopā | M33: =M31+M32 -> 12.088303 | N33: =N31+N32 -> 10.340928 | P33: =N33-M33 -> -1.7473754
D34: Viena m3 uzsildīšana karstajam ūd. (qk.ūd.(apk.sez.)) | E34: =((E19-E20)/(POWER(10,3)*E12))*E10*E11 -> 0.046522447 | F34: =ROUND(E34*E18,4) -> 1.0188 | G34: =ROUND(F34*E6,2) -> 94.72 | I34: =ROUND(G34/E18,2)+E3 -> 7.5607
F36: =E15-E26-E16 -> 1.0188 | L36: cirk(2) | M36: =U16 -> 13.536607 | N36: =V16 -> 3.560928
A37: koriģētais viena kubikmetra aukstā ūdens uzsildīšanai siltummainī patērētās siltumenerģijas daudzums norēķina periodā [MWh/m3] (qi.krģ.) | J37: =J38*E40 -> 6.4020933 | L37: x2 kubi | M37: =$U$23*2 -> 5.32 | N37: =$V$23*2 -> 6.78
A38: viena kubikmetra aukstā ūdens uzsildīšanai siltummainī patērētās siltumenerģijas daudzums karstā ūdens sagatavošanai norēķina periodā [MWh/m3] (qi) | J38: =E27 -> 6.3904 | L38: kopā | M38: =M36+M37 -> 18.856607 | N38: =N36+N37 -> 10.340928 | P38: =N38-M38 -> -8.5156787
D40: k3 | E40: =E18/P19 -> 1.0018298 | G40: koriģ.
D41: kubikmetrā(mk.ūd.) | E41: =(E33*E6)/E18 -> 4.3252477 | G41: =E41*E40 -> 4.3331622 | I41: =G41*P19 -> 94.722925
D42: Maksa norēķinu periodā(Mk.ūd.) | E42: =E18*E41 -> 94.722925
E45: =E41+E3 -> 7.5559477 | G45: =G41+E3 -> 7.5638622 | H45: =G45*E18 -> 165.64858
H47: =(G41*E18)+G16+H23 -> 729.48817
...

Sheet Rekvizīti
B3: Rēķinu starta pozīcija | C3: 436
B4: Siltums EUR: | C4: 729.3
B5: Siltums veikali EUR: | C5: 43.18
B6: Siltums dzīvokļi EUR: | C6: 686.12
B7: Rīgas Ūdens: | C7: 191.53
B8: Atkritumi: | C8: 113.72
B9: Koplietošanas elektrība: | C9: 67.43
B10: Mēnesī | C10: martā
B11: Iepriekšējais mēnesis | C11: MARTS
B12: Tekošais mēnesis (cipars) | C12: 04
B13: Tekošais mēnesis (vārds) | C13: APRĪLIS
B14: Nākošais mēnesis (vārds) | C14: MAIJS
B16: PATĒRIŅI
B17: Aukstais ūdens | C17: ='Siltuma aprēķins'!E14 -> 56.31
B18: Karstais ūdens | C18: ='Siltuma aprēķins'!E18 -> 21.9
B19: Siltuma daudzums | C19: ='Siltuma aprēķins'!E15 -> 7.81
B20: Koplietošanas elektrība | C20: =ROUND(Elektrība!F4,2) -> 278.46
B22: TARIFI:
B23: A.Ūdens | C23: 3.2307
B24: Lietus notekūdeņi | C24: 9.6074
B25: K.Ūdens | C25: =Rēķini!H2 -> 6.9107
B26: Cirkulācija | C26: ='Siltuma aprēķins'!U3 -> 6.7683034
B27: Apkure veikali | C27: ='Siltuma aprēķins'!I20 -> 0.68024904
B28: Apkure dzīvokļi | C28: ='Siltuma aprēķins'!I21 -> 0.629652
B29: Siltummezgls | C29: 0.037
B30: Vidējais Rīgas Siltums bez PVN: | C30: ='Siltuma aprēķins'!F6 -> 83.01
B31: Apsaimniekošana | C31: 0.6044
B32: Remontdarbu fonds | C32: 0.3156
B33: Alokatori: platības tarifs dz | C33: 0.2476
B34: Alokatori: vienības cena dz | C34: 0.0975
B35: Alokatori: platības tarifs saimn | C35: 0.2675
B36: Alokatori: vienības cena saimn | C36: 0.1053

Sheet Rēķini
A1: 2026 | D1: =Rekvizīti!C11 -> MARTS | E1: =Rekvizīti!C13 -> APRĪLIS | F1: =Rekvizīti!C14 -> MAIJS | H1: =H2-G2 -> 3.68 | J1: =ROUND(J2/12,2) -> 0.8 | L1: =ROUND($L$2/12,2) -> 5.62
D2: =Rekvizīti!C12 -> 04 | E2: =Rekvizīti!C31 -> 0.6044 | F2: =Rekvizīti!C32 -> 0.3156 | G2: =Rekvizīti!C23 -> 3.2307 | H2: 6.9107 | I2: =Rekvizīti!C26 -> 6.7683034 | J2: =Rekvizīti!C24 -> 9.6074 | K2: =ROUND((E33)/16,2) -> 7.11 | L2: =Elektrība!J4 -> 67.43 | M2: ='Siltuma aprēķins'!I21 -> 0.629652 | O2: =Rekvizīti!C29 -> 0.037
M3: ='Siltuma aprēķins'!I20 -> 0.68024904
E4: Apsaimniekošana | F4: Remontdarbu fonds | G4: A.ūdens | H4: K.ūdens | I4: Cirkulācija | J4: Lietus notek. | K4: Atkritumi | L4: Kopl.el. | M4: Apkure kvm 40% | N4: Apkure Alokatori 60% | O4: Siltummezgls | P4: Mērķfonds | Q4: Atlīdzība/Cits | R4: Parāds/Avanss | S4: KOPĀ EUR | T4: tikai komunālie EUR | U4: Summa vārdiem | W4: Ligitas daļa kopā | AA4: Summa vārdiem
C5: 13.9 | D5: Veikals Nr.1 | E5: =C5*$E$2 -> 8.40116 | F5: =C5*$F$2 -> 4.38684 | G5: =ROUND(Ūdens!F2*Rēķini!$G$2,2) -> 7.75 | H5: =ROUND(Ūdens!AC2,2) -> 1.31 | I5: =ROUND($I$2*Ūdens!A2,2) -> 6.77 | J5: =ROUND($J$2/12,2) -> 0.8 | K5: =$K$2*0 -> 0 | L5: =ROUND($L$2/12,2) -> 5.62 | M5: 3.72 | N5: 17.37 | O5: =ROUND(C5*$O$2,2) -> 0.51 | S5: =SUM(E5:R5) -> 56.638 | T5: =SUM(G5:N5) -> 43.34 | U5: Piecdesmit seši eiro, 64 centi | V5: salons | AA5: Piecdesmit deviņi eiro, 13 centi
C6: 41.9 | D6: Veikals Nr.2 | E6: =ROUND(C6*$E$2,2) -> 25.32 | F6: =ROUND(C6*$F$2,2) -> 13.22 | G6: =ROUND(Ūdens!F3*Rēķini!$G$2,2) -> 3.94 | H6: =ROUND(Ūdens!AC3,2) -> 1.38 | I6: =ROUND($I$2*Ūdens!A3,2) -> 6.77 | J6: =ROUND($J$2/12,2) -> 0.8 | K6: =ROUND($K$2*1,2) -> 7.11 | L6: =ROUND($L$2/12,2) -> 5.62 | M6: 11.21 | N6: 68.69 | O6: =ROUND(C6*$O$2,2) -> 1.55 | S6: =SUM(E6:R6) -> 145.61 | T6: =SUM(G6:N6) -> 105.52 | U6: Viens simts četrdesmit pieci eiro, 61 cents | V6: veikals | W6: =T6+T5+T7 -> 261.3
A7: 3.dz. | C7: 111.1 | D7: 3.dz.Ligita | E7: =ROUND(C7*$E$2,2) -> 67.15 | F7: =ROUND(C7*$F$2,2) -> 35.06 | G7: =ROUND(Ūdens!AB4,2) -> 1.84 | H7: =ROUND(Ūdens!AC4,2) -> 0.96 | I7: =ROUND($I$2*Ūdens!A4,2) -> 16.92 | J7: =ROUND($J$2/12,2) -> 0.8 | K7: =ROUND($K$2,2) -> 7.11 | L7: =ROUND($L$2/12,2) -> 5.62 | M7: 27.51 | N7: 51.68 | O7: =ROUND(C7*$O$2,2) -> 4.11 | S7: =SUM(E7:R7) -> 218.76 | T7: =SUM(G7:N7) -> 112.44 | U7: Divi simti astoņpadsmit eiro, 76 centi | V7: 3.dz. | AA7: Viens tūkstotis trīs simti sešpadsmit eiro, 52 centi
A8: 4.dz. | C8: 109.4 | D8: 4.dz. Hedija, Henrijs | E8: =ROUND(C8*$E$2,2) -> 66.12 | G8: =ROUND(Ūdens!AB5,2) -> 12.25 | H8: =ROUND(Ūdens!AC5,2) -> 18.31 | I8: =ROUND($I$2*Ūdens!A5,2) -> 16.92 | J8: =ROUND($J$2/12,2) -> 0.8 | K8: =$K$2*2 -> 14.22 | L8: =ROUND($L$2/12,2) -> 5.62 | M8: 27.09 | N8: 49.91 | O8: =ROUND(C8*$O$2,2) -> 4.05 | Q8: =-E8-O8-30 -> -100.17 | S8: =SUM(E8:Q8) -> 115.12 | T8: =SUM(G8:N8) -> 145.12 | U8: Viens simts piecpadsmit eiro, 12 centi | V8: 4.dz. | Y8: =SUM(G8:Q8) -> 49 | AA8: Astoņdesmit seši eiro, 74 centi
A9: 6.dz. | C9: 28.4 | D9: 6.dz.Ilze | E9: =C9*$E$2 -> 17.16496 | G9: =ROUND(Ūdens!F6*Rēķini!$G$2,2) -> 0.16 | H9: =ROUND(Ūdens!G6*Rēķini!$H$2,2) -> 0.28 | I9: =ROUND($I$2*Ūdens!A6,2) -> 6.77 | J9: =ROUND($J$2/12,2) -> 0.8 | K9: =K2*0 -> 0 | L9: =ROUND($L$2/12,2) -> 5.62 | M9: 7.03 | N9: 0 | O9: =ROUND(C9*$O$2,2) -> 1.05 | Q9: =-E9-O9 -> -18.21496 | S9: =SUM(E9:Q9) -> 20.66 | T9: =SUM(G9:N9) -> 20.66 | U9: Divdesmit eiro, 66 centi | V9: 6.dz. | Y9: =SUM(G9:Q9) -> 3.49504 | AA9: Piecdesmit četri eiro, 53 centi
A10: 7.dz. | C10: 84.7 | D10: 7dz. Hedija | E10: =ROUND(C10*$E$2,2) -> 51.19 | G10: =Ūdens!AB7 -> 18 | H10: =Ūdens!AC7 -> 23.57 | I10: =ROUND(($I$2*Ūdens!A7),2) -> 13.54 | J10: =ROUND($J$2/12,2) -> 0.8 | K10: =$K$2*3 -> 21.33 | L10: =ROUND($L$2/12,2) -> 5.62 | M10: 20.98 | N10: 36.02 | O10: =ROUND(C10*$O$2,2) -> 3.13 | Q10: =-E10-O10-21.23 -> -75.55 | S10: =SUM(E10:Q10) -> 118.63 | T10: =SUM(G10:N10) -> 139.86 | U10: Viens simts astoņpadsmit eiro, 63 centi | V10: 7.dz. | AA10: Septiņi simti trīspadsmit eiro, 58 centi
A11: 8.dz. | C11: 47.8 | D11: 8dz.. Zane | E11: =ROUND(C11*$E$2,2) -> 28.89 | G11: =Ūdens!AB8 -> 21.58 | H11: =Ūdens!AC8 -> 26.74 | I11: =ROUND($I$2*Ūdens!A8,2) -> 6.77 | J11: =ROUND($J$2/12,2) -> 0.8 | K11: =ROUND($K$2*2,2) -> 14.22 | L11: =ROUND($L$2/12,2) -> 5.62 | M11: 11.84 | N11: 7.88 | O11: =ROUND(C11*$O$2,2) -> 1.77 | Q11: =-E11-O11 -> -30.66 | S11: =SUM(E11:Q11) -> 95.45 | T11: =SUM(G11:N11) -> 95.45 | U11: Deviņdesmit pieci eiro, 45 centi | V11: 8.dz. | AA11: Чотириста тридцять сім євро 17 центів
A12: 9.dz. | C12: 65.7 | D12: 9.dz. Zane | E12: =C12*$E$2 -> 39.70908 | G12: =Ūdens!AB9 -> 0 | H12: =Ūdens!AC9 -> 0 | I12: =ROUND(($I$2*Ūdens!A9),2) -> 13.54 | J12: =ROUND($J$2/12,2) -> 0.8 | K12: =ROUND($K$2,2) -> 7.11 | L12: =ROUND($L$2/12,2) -> 5.62 | M12: 16.27 | N12: 0 | O12: =ROUND(C12*$O$2,2) -> 2.43 | Q12: =-E12-O12 -> -42.13908 | S12: =SUM(E12:Q12) -> 43.34 | T12: =SUM(G12:N12) -> 43.34 | U12: Četrdesmit trīs eiro, 34 centi | V12: 9.dz. | AA12: Viens simts sešdesmit seši eiro, 76 centi
A13: 10.dz. | C13: 47.1 | D13: 10.dz. Ilze | E13: =ROUND(C13*$E$2,2) -> 28.47 | G13: =ROUND(Ūdens!AB10,2) -> 10.18 | H13: =ROUND(Ūdens!AC10,2) -> 24.67 | I13: =ROUND($I$2*Ūdens!A10,2) -> 6.77 | J13: =ROUND($J$2/12,2) -> 0.8 | K13: =ROUND($K$2*1,2) -> 7.11 | L13: =ROUND($L$2/12,2) -> 5.62 | M13: 11.66 | N13: 7.17 | O13: =ROUND(C13*$O$2,2) -> 1.74 | Q13: =-E13-O13 -> -30.21 | S13: =SUM(E13:Q13) -> 73.98 | T13: =SUM(G13:N13) -> 73.98 | U13: Septiņdesmit trīs eiro, 98 centi | V13: 10.dz. | AA13: Viens simts trīsdesmit četri eiro, 22 centi
A14: 11.dz | C14: 64.4 | D14: 11.dz. Kārlis | E14: =C14*$E$2 -> 38.92336 | G14: =ROUND(Ūdens!AB11,2) -> 26.11 | H14: =ROUND(Ūdens!AC11,2) -> 40.22 | I14: =ROUND($I$2*Ūdens!A11,2) -> 13.54 | J14: =ROUND($J$2/12,2) -> 0.8 | K14: =ROUND($K$2*3,2) -> 21.33 | L14: =ROUND($L$2/12,2) -> 5.62 | M14: 15.95 | N14: 47.36 | O14: =ROUND(C14*$O$2,2) -> 2.38 | S14: =SUM(E14:R14) -> 212.23336 | T14: =SUM(G14:N14) -> 170.93 | U14: Divi simti divpadsmit eiro, 23 centi | V14: 11.dz. | AA14: Viens simts piecpadsmit eiro, 33 centi
A15: 12.dz. | B15: 93.7 | C15: 99.1 | D15: 12.dz. Kārlis | E15: =ROUND(C15*$E$2,2) -> 59.9 | G15: =Ūdens!X12+Ūdens!Z12 -> 18.28 | H15: =Ūdens!Y12+Ūdens!AA12 -> 14.45 | I15: =ROUND($I$2*Ūdens!A12,2) -> 16.92 | J15: =ROUND($J$2/12,2) -> 0.8 | K15: =ROUND($K$2*2,2) -> 14.22 | L15: =ROUND($L$2/12,2) -> 5.62 | M15: 23.2 | N15: 17.84 | O15: =ROUND(C15*$O$2,2) -> 3.67 | S15: =SUM(E15:Q15) -> 174.9 | T15: =SUM(G15:N15) -> 111.33 | U15: Viens simts septiņdesmit četri eiro, 90 centi | V15: 12.dz. | Y15: =SUM(G15:Q15) -> 115 | AA15: Viens simts divdesmit septiņi eiro, 63 centi
A16: Pagrabs | C16: 98.3 | D16: Ilze | E16: =ROUND(C16*$E$2,2) -> 59.41 | G16: =Ūdens!AB13 -> 0 | H16: =ROUND(Ūdens!G13*Rēķini!$H$2,2) -> 0.48 | I16: =ROUND($I$2*Ūdens!A13,2) -> 6.77 | J16: =ROUND($J$2/12,2) -> 0.8 | K16: 0 | L16: =ROUND($L$2/12,2) -> 5.62 | M16: 24.34 | N16: 2.05 | O16: =ROUND(C16*$O$2,2) -> 3.64 | Q16: =-E16-O16 -> -63.05 | S16: =SUM(E16:R16) -> 40.06 | T16: =SUM(G16:N16) -> 40.06 | U16: Četrdesmit eiro, 06 centi | V16: pagrabs | AA16: Deviņdesmit seši eiro, 86 centi
C17: 109.4 | D17: 4.dz. Hedija, Henrijs | F17: 34.53 | S17: =F17 -> 34.53
C18: 28.4 | D18: 6.dz.Ilze | F18: 8.96 | S18: =F18 -> 8.96
C19: 84.7 | D19: 7dz. Hedija | F19: 26.73 | S19: =F19 -> 26.73
C20: 47.8 | D20: 8.dz. Zane | F20: 15.09 | S20: =F20 -> 15.09
C21: 65.7 | D21: 9.dz. Zane | F21: 20.73 | S21: =F21 -> 20.73
C22: 47.1 | D22: 10.dz. Ilze | F22: 14.86 | S22: =F22 -> 14.86
C23: 64.4 | D23: 11.dz. Kārlis | F23: 20.32 | S23: =F23 -> 20.32
C24: 99.1 | D24: 12.dz. Kārlis | F24: 31.28 | S24: =F24 -> 31.28
C25: 98.3 | D25: Ilze | F25: 31.02 | S25: =F25 -> 31.02
C26: =C6+C5+C7+C8+C9+C10+C11+C12+C13+C14+C15+C16 -> 811.8 | D26: TOTAL | E26: =SUM(E5:E25) -> 490.64856 | F26: =SUM(F5:F25) -> 256.18684 | G26: =SUM(G5:G25) -> 120.09 | H26: =SUM(H5:H25) -> 152.37 | I26: =SUM(I5:I25) -> 132 | J26: =SUM(J5:J25) -> 9.6 | K26: =SUM(K5:K25) -> 113.76 | L26: =SUM(L5:L25) -> 67.44 | ... P26: =SUM(P5:P25) -> 0 | Q26: =SUM(Q5:Q25)-Q14 -> -359.99404 | R26: =SUM(R5:R25) -> 0 | S26: =SUM(S5:S25) -> 1518.9014 | T26: =SUM(T5:T25) -> 1102.03 | U26: =S27-T26 -> 160.68452
D27: Apsaimniekošanas un siltummezgla reālais ienākums | E27: =E5+O5+E6+O6+E7+O7+E14+O14+E15+O15 -> 211.91452 | Q27: =-E8-O8-E9-O9-E10-O10-E11-O11-E12-O12-E13-O13-E16-O16 -> -308.76404 | S27: =S26-F26 -> 1262.7145
D28: Apsaimniekošanas atlikums | E28: =E26+Q26+O26 -> 160.68452 | Q28: =Q26-Q27 -> -51.23 | S28: =SUM(S5:S16) -> 1315.3814
D30: =Rekvizīti!C10 -> martā | E30: Izdevumi | F30: Aprēķins | H30: Nesakrīt:
D31: Rīgas Ūdens | E31: =ROUND(Rekvizīti!C7,2) -> 191.53 | F31: =G26+(Ūdens!G14*G2)+J26 -> 200.3131 | H31: =F31-E31 -> 8.783102
D32: Rīgas Siltums | E32: =ROUND(Rekvizīti!C4,2) -> 729.3 | F32: =I26+(H26-(Ūdens!G14*G2))+M26+N26 -> 720.5169 | H32: =F32-E32 -> -8.783102 | J32: =H31+H32 -> -1.1368684e-13 | R32: Apsaimniekošanas un siltummezgla apkalpošanas ieņēmumi
D33: Clean atkritumi | E33: =ROUND(Rekvizīti!C8,2) -> 113.72 | F33: =K26 -> 113.76 | H33: =F33-E33 -> 0.04 | R33: =E5+E6+E7+E14+E15+O5+O6+O7+O14+O15+Q28 -> 160.68452 | S33: =SUM(E5:E16)+Q8+Q9+Q10+Q11+Q12+Q13+Q16+SUM(O5:O16) -> 160.68452
D34: Elektroenerģija | E34: =Elektrība!J4 -> 67.43 | F34: =L26 -> 67.44 | H34: =F34-E34 -> 0.01 | O34: =SUM(H31:H34) -> 0.05
D35: Atlīdzība | E35: 360 | F35: =-(Q26) -> 359.99404 | H35: =F35-E35 -> -0.00596
D36: Nodokļi
D37: Siltummezgls | E37: 0 | F37: =O26 -> 30.03 | H37: =F37-E37 -> 30.03
D38: Pagraba signalizācija abon. | E38: 22.39 | F38: =R16 -> 0 | H38: =F38-E38 -> -22.39
D39: Alokatoru apkalpošana | E39: 0 | F39: 0 | H39: =F39-E39 -> 0
D40: Apsaimniekošana | F40: =E28 -> 160.68452 | H40: =F40-E40 -> 160.68452
E41: =SUM(E31:E40) -> 1484.37 | F41: =SUM(F31:F38) -> 1492.054 | H41: =SUM(H31:H40) -> 168.36856
...

Sheet Mēneša Kopsummas
B1: Iedzīvotāji | D1: =Rēķini!S4 -> KOPĀ EUR | E1: =Rēķini!#REF! -> #REF! | F1: =Rēķini!T4 -> tikai komunālie EUR | G1: =Rēķini!#REF! -> #REF! | H1: Parādi/Avansi | I1: Kopā EUR | J1: depozīts
A2: Ksenija | B2: 0 | C2: =Rēķini!D5 -> Veikals Nr.1 | D2: =Rēķini!S5 -> 56.638
A3: Aleksandrs | B3: 1 | C3: =Rēķini!D6 -> Veikals Nr.2 | D3: =Rēķini!S6 -> 145.61 | E3: =Rēķini!#REF! -> #REF! | F3: =Rēķini!T6 -> 105.52 | G3: =Rēķini!#REF! -> #REF!
A4: Ligita | B4: 1 | C4: =Rēķini!D7 -> 3.dz.Ligita | D4: =Rēķini!S7 -> 218.76 | E4: =Rēķini!#REF! -> #REF! | F4: =Rēķini!T7 -> 112.44 | G4: =Rēķini!#REF! -> #REF!
A5: Hedija | B5: 2 | C5: =Rēķini!D8 -> 4.dz. Hedija, Henrijs | D5: =Rēķini!S8 -> 115.12 | E5: =Rēķini!#REF! -> #REF! | F5: =SUM(Rēķini!G8:O8) -> 149.17 | G5: =Rēķini!#REF! -> #REF!
A6: Ilze | B6: 0 | C6: =Rēķini!D9 -> 6.dz.Ilze | D6: =Rēķini!S9 -> 20.66 | E6: =Rēķini!#REF! -> #REF! | F6: =Rēķini!T9 -> 20.66 | G6: =Rēķini!#REF! -> #REF!
A7: Hedija | B7: 3 | C7: =Rēķini!D10 -> 7dz. Hedija | D7: =Rēķini!S10 -> 118.63 | E7: =Rēķini!#REF! -> #REF! | F7: =SUM(Rēķini!G10:L10)+SUM(Rēķini!M10:O10) -> 142.99 | G7: =Rēķini!#REF! -> #REF!
A8: Ilze | B8: 2 | C8: =Rēķini!D11 -> 8dz.. Zane | D8: =Rēķini!S11 -> 95.45 | E8: =Rēķini!#REF! -> #REF! | F8: =Rēķini!T11 -> 95.45 | G8: =Rēķini!#REF! -> #REF!
A9: Ilze | B9: 1 | C9: =Rēķini!D12 -> 9.dz. Zane | D9: =Rēķini!S12 -> 43.34 | E9: =Rēķini!#REF! -> #REF! | F9: =Rēķini!T12 -> 43.34 | G9: =Rēķini!#REF! -> #REF!
A10: Ilze | B10: 1 | C10: =Rēķini!D13 -> 10.dz. Ilze | D10: =Rēķini!S13 -> 73.98 | E10: =Rēķini!#REF! -> #REF! | F10: =Rēķini!T13 -> 73.98 | G10: =Rēķini!#REF! -> #REF!
A11: Kārlis | B11: 3 | C11: =Rēķini!D14 -> 11.dz. Kārlis | D11: =Rēķini!S14 -> 212.23336 | E11: =Rēķini!#REF! -> #REF! | F11: =Rēķini!T14 -> 170.93 | G11: =Rēķini!#REF! -> #REF!
A12: Kārlis | B12: 2 | C12: =Rēķini!D15 -> 12.dz. Kārlis | D12: =Rēķini!S15 -> 174.9 | E12: =Rēķini!#REF! -> #REF! | F12: =Rēķini!T15 -> 111.33 | G12: =Rēķini!#REF! -> #REF!
A13: Hedija/Ilze | B13: 0 | C13: =Rēķini!A16 -> Pagrabs | D13: =Rēķini!S16 -> 40.06 | E13: =Rēķini!#REF! -> #REF! | F13: =Rēķini!S16 -> 40.06
B14: =SUM(B2:B13) -> 16 | C14: KOPĀ: | D14: =SUM(D2:D13) -> 1315.3814 | F14: =SUM(F3:F13) -> 1065.87
G16: =F16*0.7028 -> 0

Sheet Ūdens
E1: apkure | F1: A.ūd. | G1: Vk.ūd.patēr. | J1: Aped | K1: Atag | L1: Kped | M1: Ktag | N1: Aped | O1: Atag | P1: Kped | Q1: Ktag | R1: Sum A1 | S1: Sum K1 | T1: Sum A2 | U1: Sum K2 | V1: A | W1: K | X1: A1 € | Y1: K1 € | Z1: A2 € | AA1: K2 € | AB1: =Rēķini!G2 -> 3.2307 | AC1: =Rēķini!H2 -> 6.9107
A2: 1 | B2: Veikals Nr.1 | C2: 13.9 | F2: =V2 -> 2.4 | G2: =W2 -> 0.19 | J2: 1.58 | K2: 3.98 | L2: 0.28 | M2: 0.47 | R2: =K2-J2 -> 2.4 | S2: =M2-L2 -> 0.19 | V2: =K2-J2 -> 2.4 | W2: =M2-L2 -> 0.19 | X2: =ROUND(R2*$AB$1,2) -> 7.75 | Y2: =ROUND(S2*$AC$1,2) -> 1.31 | AB2: =V2*$AB$1 -> 7.75368 | AC2: =W2*$AC$1 -> 1.313033 | AD2: Salons
A3: 1 | B3: Veikals Nr.2 | C3: 41.9 | F3: =V3 -> 1.22 | G3: =W3 -> 0.2 | J3: 5.8 | K3: 7.02 | L3: 0.99 | M3: 1.19 | R3: =K3-J3 -> 1.22 | S3: =M3-L3 -> 0.2 | V3: =K3-J3 -> 1.22 | W3: =M3-L3 -> 0.2 | X3: =R3*$AB$1 -> 3.941454 | Y3: =S3*$AC$1 -> 1.38214 | AB3: =V3*$AB$1 -> 3.941454 | AC3: =W3*$AC$1 -> 1.38214 | AD3: Veikals
A4: 2.5 | B4: Dzīvoklis Nr.3 - L.Loeve | C4: 111.04 | F4: =V4 -> 0.57 | G4: =W4 -> 0.14 | J4: 0.77 | K4: 1.29 | L4: 0.25 | M4: 0.31 | N4: 0.01 | O4: 0.06 | P4: 0.07 | Q4: 0.15 | R4: =K4-J4 -> 0.52 | S4: =M4-L4 -> 0.06 | T4: =O4-N4 -> 0.05 | U4: =Q4-P4 -> 0.08 | V4: =(K4-J4)+(O4-N4) -> 0.57 | W4: =(M4-L4)+(Q4-P4) -> 0.14 | X4: =ROUND(R4*$AB$1,2) -> 1.68 | Y4: =ROUND(S4*$AC$1,2) -> 0.41 | Z4: =ROUND(T4*$AB$1,2) -> 0.16 | AA4: =ROUND(U4*$AC$1,2) -> 0.55 | AB4: =X4+Z4 -> 1.84 | AC4: =Y4+AA4 -> 0.96 | AD4: Dz.3
A5: 2.5 | B5: Dzīvoklis Nr.4 Hedija | C5: 109.4 | F5: =V5 -> 3.79 | G5: =W5 -> 2.65 | J5: 12.34 | K5: 15.8 | L5: 5.36 | M5: 7.01 | N5: 1.45 | O5: 1.78 | P5: 4.06 | Q5: 5.06 | R5: =K5-J5 -> 3.46 | S5: =M5-L5 -> 1.65 | T5: =O5-N5 -> 0.33 | U5: =Q5-P5 -> 1 | V5: =(K5-J5)+(O5-N5) -> 3.79 | W5: =(M5-L5)+(Q5-P5) -> 2.65 | X5: =ROUND(R5*$AB$1,2) -> 11.18 | Y5: =ROUND(S5*$AC$1,2) -> 11.4 | Z5: =ROUND(T5*$AB$1,2) -> 1.07 | AA5: =ROUND(U5*$AC$1,2) -> 6.91 | AB5: =X5+Z5 -> 12.25 | AC5: =Y5+AA5 -> 18.31 | AD5: Dz.4
A6: 1 | B6: Dzīvoklis Nr.6 Ilze | C6: 28.4 | F6: =V6 -> 0.05 | G6: =W6 -> 0.04 | J6: 0.26 | K6: 0.31 | L6: 0.16 | M6: 0.2 | R6: =K6-J6 -> 0.05 | S6: =M6-L6 -> 0.04 | V6: =(K6-J6)+(O6-N6) -> 0.05 | W6: =(M6-L6)+(Q6-P6) -> 0.04 | X6: =ROUND(R6*$AB$1,2) -> 0.16 | Y6: =ROUND(S6*$AC$1,2) -> 0.28 | AB6: =ROUND(V6*$AB$1,2) -> 0.16 | AC6: =ROUND(W6*$AC$1,2) -> 0.28 | AD6: Dz.6
A7: 2 | B7: Dzīvoklis Nr.7 Kristīne | C7: 84.7 | F7: =V7 -> 5.57 | G7: =W7 -> 3.41 | J7: 12.97 | K7: 15.83 | L7: 12.51 | M7: 15.11 | N7: 11.81 | O7: 14.52 | P7: 4.26 | Q7: 5.07 | R7: =K7-J7 -> 2.86 | S7: =M7-L7 -> 2.6 | T7: =O7-N7 -> 2.71 | U7: =Q7-P7 -> 0.81 | V7: =(K7-J7)+(O7-N7) -> 5.57 | W7: =(M7-L7)+(Q7-P7) -> 3.41 | X7: =ROUND(R7*$AB$1,2) -> 9.24 | Y7: =ROUND(S7*$AC$1,2) -> 17.97 | Z7: =ROUND(T7*$AB$1,2) -> 8.76 | AA7: =ROUND(U7*$AC$1,2) -> 5.6 | AB7: =X7+Z7 -> 18 | AC7: =Y7+AA7 -> 23.57 | AD7: Dz.7
A8: 1 | B8: Dzīvoklis Nr.8 Anastasiia | C8: 47.8 | F8: =V8 -> 6.68 | G8: =W8 -> 3.87 | J8: 32.34 | K8: 39.02 | L8: 18.35 | M8: 22.22 | R8: =K8-J8 -> 6.68 | S8: =M8-L8 -> 3.87 | V8: =(K8-J8)+(O8-N8) -> 6.68 | W8: =(M8-L8)+(Q8-P8) -> 3.87 | X8: =R8*$AB$1 -> 21.581076 | Y8: =S8*$AC$1 -> 26.744409 | AB8: =ROUND(V8*$AB$1,2) -> 21.58 | AC8: =ROUND(W8*$AC$1,2) -> 26.74 | AD8: Dz.8
A9: 2 | B9: Dzīvoklis Nr.9 Mārtiņš | C9: 65.7 | F9: =V9 -> 0 | G9: =W9 -> 0 | J9: 0.17 | K9: 0.17 | L9: 0.63 | M9: 0.63 | N9: 1.35 | O9: 1.35 | P9: 0.11 | Q9: 0.11 | R9: =K9-J9 -> 0 | S9: =M9-L9 -> 0 | T9: =O9-N9 -> 0 | U9: =Q9-P9 -> 0 | V9: =(K9-J9)+(O9-N9) -> 0 | W9: =(M9-L9)+(Q9-P9) -> 0 | X9: =ROUND(R9*$AB$1,2) -> 0 | Y9: =ROUND(S9*$AC$1,2) -> 0 | Z9: =ROUND(T9*$AB$1,2) -> 0 | AA9: =ROUND(U9*$AC$1,2) -> 0 | AB9: =X9+Z9 -> 0 | AC9: =Y9+AA9 -> 0 | AD9: Dz.9
A10: 1 | B10: Dzīvoklis Nr.10 Anna | C10: 47.1 | F10: =V10 -> 3.15 | G10: =W10 -> 3.57 | J10: 9.86 | K10: 13.01 | L10: 12.03 | M10: 15.6 | R10: =K10-J10 -> 3.15 | S10: =M10-L10 -> 3.57 | V10: =(K10-J10)+(O10-N10) -> 3.15 | W10: =(M10-L10)+(Q10-P10) -> 3.57 | X10: =R10*$AB$1 -> 10.176705 | Y10: =S10*$AC$1 -> 24.671199 | AB10: =V10*$AB$1 -> 10.176705 | AC10: =W10*$AC$1 -> 24.671199 | AD10: Dz.10
A11: 2 | B11: Dzīvoklis Nr.11 Monta&Eduards | C11: 64.4 | F11: =V11 -> 8.08 | G11: =W11 -> 5.82 | J11: 4.36 | K11: 5.86 | L11: 4.87 | M11: 6.15 | N11: 27.12 | O11: 33.7 | P11: 18.54 | Q11: 23.08 | R11: =K11-J11 -> 1.5 | S11: =M11-L11 -> 1.28 | T11: =O11-N11 -> 6.58 | U11: =Q11-P11 -> 4.54 | V11: =(K11-J11)+(O11-N11) -> 8.08 | W11: =(M11-L11)+(Q11-P11) -> 5.82 | X11: =ROUND(R11*$AB$1,2) -> 4.85 | Y11: =ROUND(S11*$AC$1,2) -> 8.85 | Z11: =ROUND(T11*$AB$1,2) -> 21.26 | AA11: =ROUND(U11*$AC$1,2) -> 31.37 | AB11: =X11+Z11 -> 26.11 | AC11: =Y11+AA11 -> 40.22 | AD11: Dz.11
A12: 2.5 | B12: Dzīvoklis Nr.12 Māris&Ruta | C12: 93.7 | D12: 99.1 | F12: =V12 -> 5.66 | G12: =W12 -> 2.09 | J12: 5.62 | K12: 6.97 | L12: 2.08 | M12: 2.66 | N12: 20.33 | O12: 24.64 | P12: 6.59 | Q12: 8.1 | R12: =K12-J12 -> 1.35 | S12: =M12-L12 -> 0.58 | T12: =O12-N12 -> 4.31 | U12: =Q12-P12 -> 1.51 | V12: =(K12-J12)+(O12-N12) -> 5.66 | W12: =(M12-L12)+(Q12-P12) -> 2.09 | X12: =ROUND(R12*$AB$1,2) -> 4.36 | Y12: =ROUND(S12*$AC$1,2) -> 4.01 | Z12: =ROUND(T12*$AB$1,2) -> 13.92 | AA12: =ROUND(U12*$AC$1,2) -> 10.44 | AB12: =X12+Z12 -> 18.28 | AC12: =Y12+AA12 -> 14.45 | AD12: Dz.12
A13: 1 | B13: Pagrabs | C13: 78.7 | F13: =V13 -> 0 | G13: =W13 -> 0.07 | J13: 0.7 | K13: 0.7 | L13: 0.12 | M13: 0.19 | N13: 0.01 | O13: 0.01 | R13: =K13-J13 -> 0 | S13: =M13-L13 -> 0.07 | T13: =O13-N13 -> 0 | V13: =(K13-J13)+(O13-N13) -> 0 | W13: =M13-L13 -> 0.07 | X13: =ROUND(R13*$AB$1,2) -> 0 | Y13: =ROUND(S13*$AC$1,2) -> 0.48 | Z13: =ROUND(T13*$AB$1,2) -> 0 | AB13: =X13+Z13 -> 0 | AC13: =Y13 -> 0.48 | AD13: Pagrabs
A14: =SUM(A3:A13) -> 18.5 | C14: 786.74 | F14: =SUM(F3:F13) -> 34.77 | G14: =SUM(G3:G13) -> 21.86 | X14: =ROUND($X$13/4,2) -> 0 | Y14: =ROUND($Y$13/4,2) -> 0.12 | Z14: =ROUND($Z$13/4,2) -> 0 | AB14: =X14+Z14 -> 0 | AC14: =Y14 -> 0.12
X15: =ROUND($X$13/2,2) -> 0 | Y15: =ROUND($Y$13/2,2) -> 0.24 | Z15: =ROUND($Z$13/2,2) -> 0 | AB15: =X15+Z15 -> 0 | AC15: =Y15 -> 0.24
B17: ūdens kopā | C17: =H14
B18: k.ūd | C18: =G14 -> 21.86
B19: a.ūd. | C19: =F14 -> 34.77 | F19: =F6/3 -> 0.016666667 | G19: =G6/3 -> 0.013333333
J27: =K11-J11 -> 1.5 | L27: =M11-L11 -> 1.28 | N27: =O11-N11 -> 6.58 | P27: =Q11-P11 -> 4.54
J28: =K12-J12 -> 1.35 | L28: =M12-L12 -> 0.58 | N28: =O12-N12 -> 4.31
O49: 9

Sheet Elektrība
A1: 1kwh | B1: Amp | C1: Elektrība | D1: Iepriekš | E1: Tekošais | F1: Patēriņš | G1: Tarifs | H1: pamata | I1: kopā (no rēķina TET bez PVN) | J1: Kopā ar PVN | M1: 1kwh | W1: pvn | X1: kopā ar pvn
A2: =J2/F2 -> #DIV/0! | B2: 25 | C2: Dz.11 | D2: 6760.46 | E2: 6760.46 | F2: =E2-D2 -> 0 | G2: 0.1164 | H2: 0.1515 | J2: =I2+(I2/100*21) -> 0 | M2: =J2/F2 -> #DIV/0! | W2: =V2/100*21 -> 0 | X2: =V2+W2 -> 0 | Y2: =F2 -> 0 | Z2: =$AB$18 -> 0.1599983 | AA2: =Y2*Z2 -> 0 | AB2: =$Q$10 -> 0 | AC2: =AA2+AB2 -> 0 | AH2: 36 | AI2: =$AB$18 -> 0.1599983 | AJ2: =AH2*AI2 -> 5.7599388 | AK2: 0.2 | AL2: =AJ2+AK2 -> 5.9599388 | AN2: =X2+AG2 -> 0 | AO2: =Y2+AH2 -> 36 | AP2: =AI2 -> 0.1599983 | AQ2: =AO2*AP2 -> 5.7599388
A3: =J3/F3 -> #DIV/0! | B3: 25 | C3: Dz.12 | D3: 14038.42 | E3: 14038.42 | F3: =E3-D3 -> 0 | G3: 0.1164 | H3: 0.1515 | J3: =I3+(I3/100*21) -> 0 | M3: =J3/F3 -> #DIV/0! | W3: =V3/100*21 -> 0 | X3: =V3+W3 -> 0 | Y3: =F3 -> 0 | Z3: =$AB$18 -> 0.1599983 | AA3: =Y3*Z3 -> 0 | AB3: 0.25 | AC3: =AA3+AB3 -> 0.25 | AH3: 70 | AI3: =$AB$18 -> 0.1599983 | AJ3: =AH3*AI3 -> 11.199881 | AK3: 0.2 | AL3: =AJ3+AK3 -> 11.399881 | AN3: =X3+AG3 -> 0 | AO3: =Y3+AH3 -> 70 | AP3: =AI3 -> 0.1599983 | AQ3: =AO3*AP3 -> 11.199881
A4: =J4/F4 -> 0.24215327 | B4: 25 | C4: Koplietošana | D4: 28024.36 | E4: 28302.82 | F4: =E4-D4 -> 278.46 | G4: 0.1164 | H4: 0.1515 | I4: 55.73 | J4: =ROUND(I4+(I4/100*21),2) -> 67.43 | M4: =J4/F4 -> 0.24215327 | W4: =V4/100*21 -> 0 | X4: =V4+W4 -> 0 | Y4: =F4 -> 278.46 | Z4: =$AB$18 -> 0.1599983 | AA4: =Y4*Z4 -> 44.553127 | AC4: =AA4+AB4 -> 44.553127 | AH4: 59 | AI4: =$AB$18 -> 0.1599983 | AJ4: =AH4*AI4 -> 9.4398997 | AK4: 0.2 | AL4: =AJ4+AK4 -> 9.6398997 | AN4: =X4+AG4 -> 0 | AO4: =Y4+AH4 -> 337.46 | AP4: =AI4 -> 0.1599983 | AQ4: =AO4*AP4 -> 53.993026
AA6: =#REF!+#REF! -> #REF!
G8: =L3-J3 -> 0 | H8: =G8*G3 -> 0 | AO8: =#REF!*AI4 -> #REF!
AB11: 0.04904 | AC11: 0.04904
AB12: 0.0564 | AC12: 0.0564
AB13: 0.00942 | AC13: 0.00942
AB14: 0.01737 | AC14: 0.01737
AB15: =SUM(AB11:AB14) -> 0.13223 | AC15: =SUM(AC11:AC14) -> 0.13223
AB17: =AB15/100*21 -> 0.0277683
AB18: =AB15+AB17 -> 0.1599983

Sheet veikals 1
A2: =TODAY() -> 46135 | E2: =_xlfn.TEXTJOIN("",TRUE,"Rēķins Nr. B",Rēķini!A1,Rēķini!D2,"0",Rekvizīti!C3) -> Rēķins Nr. B2026040436
A4: Piegādātājs: Dzīvokļu īpašnieku biedrība "Brīvības 166" | E4: Saņēmējs: Ksenija Labada
A5: Jur. Adrese: Brīvības 166-4, Rīga | E5: Adrese: Brīvības 166-1, Rīga LV-1012
A6: Reģ. nr. 40008324442
A7: “Swedbank” AS, SWIFT: HABALV22
A8: Konts: LV43HABA0551054594820
A10: =_xlfn.TEXTJOIN("",TRUE,"Komunālo pakalpojumu sniegšanas periods: ","2025. gada ",Rēķini!$D$1) -> Komunālo pakalpojumu sniegšanas periods: 2025. gada MARTS
A11: =_xlfn.TEXTJOIN("",TRUE,"Apsaimniekošana, remontdarbu fonds: ",Rēķini!$A$1,". gada ",Rēķini!$E$1) -> Apsaimniekošana, remontdarbu fonds: 2026. gada APRĪLIS
A13: Rēķina apmaksas termiņš: | B13: =DATE(Rēķini!A1,Rēķini!$D$2,30) -> 46142
A15: Nosaukums | D15: Mērvien. | E15: Daudz. | F15: Cena (EUR) | G15: Summa (EUR)
A17: Apsaimniekošana | D17: m2 | E17: 13.9 | F17: 0.6044 | G17: =E17*F17 -> 8.40116
A18: Remontdarbu fonds | D18: m2 | E18: 13.9 | F18: 0.3156 | G18: =E18*F18 -> 4.38684
A19: Ūdens apgāde un kanalizācija
A20: =_xlfn.TEXTJOIN(" ",TRUE,"Aukstā ūdens skaitītājs (rād:",Ūdens!J2,"-", Ūdens!K2, ")") -> Aukstā ūdens skaitītājs (rād: 1,58 - 3,98 ) | D20: m3 | E20: =Ūdens!R2 -> 2.4 | F20: =Rēķini!G2 -> 3.2307 | G20: =Ūdens!X2 -> 7.75
A21: =_xlfn.TEXTJOIN(" ",TRUE,"Karstā ūdens skaitītājs (rād:",Ūdens!L2,"-", Ūdens!M2, ")") -> Karstā ūdens skaitītājs (rād: 0,28 - 0,47 ) | D21: m3 | E21: =Ūdens!S2 -> 0.19 | F21: =Rēķini!H2 -> 6.9107 | G21: =Ūdens!Y2 -> 1.31
A22: Cirkulācija* | D22: telpa | E22: 1 | F22: =Rēķini!I5 -> 6.77 | G22: =Rēķini!I5 -> 6.77
A23: Lietus notekūdeņi | D23: mēnesis | E23: 1 | F23: =Rēķini!J5 -> 0.8 | G23: =Rēķini!J5 -> 0.8
A24: Atkritumu izvešana | D24: iedz. | E24: 1 | F24: =Rēķini!K2 -> 7.11 | G24: =Rēķini!K5 -> 0
A25: Koplietošanas elektrība*** | D25: telpa | E25: 1 | F25: =Rēķini!L5 -> 5.62 | G25: =Rēķini!L5 -> 5.62
A26: Apkure (kopējā) 40% | D26: m2 | E26: =Rēķini!C5 -> 13.9 | F26: =Rekvizīti!C35 -> 0.2675 | G26: =Rēķini!M5 -> 3.72
A27: Apkure (patēriņš) 60% **** | D27: vienības | E27: 164.892 | F27: =Rekvizīti!C36 -> 0.1053 | G27: =Rēķini!N5 -> 17.37
A28: Siltummezgla apkalpošana | D28: m2 | E28: 13.9 | F28: =Rēķini!O2 -> 0.037 | G28: =ROUND(E28*F28,2) -> 0.51
D29: Kopā | G29: =SUM(G17:G28) -> 56.638
F30: Avansā | G30: 0
F31: Summa samaksai, EUR | G31: =G29-G30 -> 56.638
A33: =_xlfn.TEXTJOIN(" ",TRUE,"Summa vārdiem: ",Rēķini!U5) -> Summa vārdiem: Piecdesmit seši eiro, 64 centi
A36: =_xlfn.TEXTJOIN(" ",TRUE,"* Siltumenerģijas patēriņš", Rēķini!$D$30, "kopā: ",Rekvizīti!$C$19,"Mwh (",Rēķini!$E$32, "Eur)") -> * Siltumenerģijas patēriņš martā kopā: 7,81 Mwh ( 729,3 Eur)
A37: =_xlfn.TEXTJOIN(" ",TRUE,"** Atkritumu izvešana kopā:",Rēķini!$E$33,"EUR(1x nedēļā), aprēķināts uz 16 iedzīvotājiem") -> ** Atkritumu izvešana kopā: 113,72 EUR(1x nedēļā), aprēķināts uz 16 iedzīvotājiem
A38: =_xlfn.TEXTJOIN(" ",TRUE,"*** Koplietošanas elektrības patēriņš", Rēķini!$D$30, "kopā: ",Rekvizīti!$C$20,"Kwh (", Rekvizīti!$C$9, "Eur)") -> *** Koplietošanas elektrības patēriņš martā kopā: 278,46 Kwh ( 67,43 Eur)
A39: **** Apkures patēriņa daļas sadalījuma % atkarīgs no vidējās mēneša temperatūras
A44: Rēķins sagatavots elektroniski un derīgs bez paraksta

Sheet veikals 2
A2: =TODAY() -> 46135 | E2: =_xlfn.TEXTJOIN("",TRUE,"Rēķins Nr. B",Rēķini!A1,Rēķini!D2,"0",Rekvizīti!C3+1,) -> Rēķins Nr. B2026040437
A4: Piegādātājs: Dzīvokļu īpašnieku biedrība "Brīvības 166" | E4: Saņēmējs: Aleksandrs Labada
A5: Jur. Adrese: Brīvības 166-4, Rīga | E5: Adrese: Brīvības 166-2, Rīga LV-1012
A6: Reģ. nr. 40008324442
A7: “Swedbank” AS, SWIFT: HABALV22
A8: Konts: LV43HABA0551054594820
A10: =_xlfn.TEXTJOIN("",TRUE,"Komunālo pakalpojumu sniegšanas periods: ","2025. gada ",Rēķini!$D$1) -> Komunālo pakalpojumu sniegšanas periods: 2025. gada MARTS
A11: =_xlfn.TEXTJOIN("",TRUE,"Apsaimniekošana, remontdarbu fonds: ",Rēķini!$A$1,". gada ",Rēķini!$E$1) -> Apsaimniekošana, remontdarbu fonds: 2026. gada APRĪLIS
A13: Rēķina apmaksas termiņš: | B13: =DATE(Rēķini!A1,Rēķini!$D$2,30) -> 46142
A15: Nosaukums | D15: Mērvien. | E15: Daudz. | F15: Cena (EUR) | G15: Summa (EUR)
A17: Apsaimniekošana | D17: m2 | E17: 41.9 | F17: 0.6044 | G17: =ROUND(E17*F17,2) -> 25.32
A18: Remontdarbu fonds | D18: m2 | E18: 41.9 | F18: 0.3156 | G18: =ROUND(E18*F18,2) -> 13.22
A19: Ūdens apgāde un kanalizācija
A20: =_xlfn.TEXTJOIN(" ",TRUE,"Aukstā ūdens skaitītājs (rād:",Ūdens!J3,"-", Ūdens!K3, ")") -> Aukstā ūdens skaitītājs (rād: 5,8 - 7,02 ) | D20: m3 | E20: =Ūdens!R3 -> 1.22 | F20: =Rēķini!G2 -> 3.2307 | G20: =ROUND(Ūdens!X3,2) -> 3.94
A21: =_xlfn.TEXTJOIN(" ",TRUE,"Karstā ūdens skaitītājs (rād:",Ūdens!L3,"-", Ūdens!M3, ")") -> Karstā ūdens skaitītājs (rād: 0,99 - 1,19 ) | D21: m3 | E21: =Ūdens!S3 -> 0.2 | F21: =Rēķini!H2 -> 6.9107 | G21: =ROUND(Ūdens!Y3,2) -> 1.38
A22: Cirkulācija* | D22: telpa | E22: 1 | F22: =Rēķini!I6 -> 6.77 | G22: =Rēķini!I6 -> 6.77
A23: Lietus notekūdeņi | D23: mēnesis | E23: 1 | F23: =Rēķini!J6 -> 0.8 | G23: =Rēķini!J6 -> 0.8
A24: Atkritumu izvešana | D24: iedz. | E24: 1 | F24: =Rēķini!K2 -> 7.11 | G24: =Rēķini!K6 -> 7.11
A25: Koplietošanas elektrība*** | D25: telpa | E25: 1 | F25: =Rēķini!L6 -> 5.62 | G25: =Rēķini!L6 -> 5.62
A26: Apkure (kopējā) 40% | D26: m2 | E26: 41.9 | F26: =Rekvizīti!C35 -> 0.2675 | G26: =Rēķini!M6 -> 11.21
A27: Apkure (patēriņš) 60% **** | D27: vienības | E27: 652.092 | F27: =ROUND(Rekvizīti!C36,4) -> 0.1053 | G27: =Rēķini!N6 -> 68.69
A28: Siltummezgla apkalpošana | D28: m2 | E28: 41.9 | F28: =Rēķini!O2 -> 0.037 | G28: =Rēķini!O6 -> 1.55
D29: Summa samaksai, EUR | G29: =SUM(G17:G28) -> 145.61
A31: =_xlfn.TEXTJOIN(" ",TRUE,"Summa vārdiem: ",Rēķini!U6) -> Summa vārdiem: Viens simts četrdesmit pieci eiro, 61 cents
A34: =_xlfn.TEXTJOIN(" ",TRUE,"* Siltumenerģijas patēriņš", Rēķini!$D$30, "kopā: ",Rekvizīti!$C$19,"Mwh (",Rēķini!$E$32, "Eur)") -> * Siltumenerģijas patēriņš martā kopā: 7,81 Mwh ( 729,3 Eur)
A35: =_xlfn.TEXTJOIN(" ",TRUE,"** Atkritumu izvešana kopā:",Rēķini!$E$33,"EUR(1x nedēļā), aprēķināts uz 16 iedzīvotājiem") -> ** Atkritumu izvešana kopā: 113,72 EUR(1x nedēļā), aprēķināts uz 16 iedzīvotājiem
A36: =_xlfn.TEXTJOIN(" ",TRUE,"*** Koplietošanas elektrības patēriņš", Rēķini!$D$30, "kopā: ",Rekvizīti!$C$20,"Kwh (", Rekvizīti!$C$9, "Eur)") -> *** Koplietošanas elektrības patēriņš martā kopā: 278,46 Kwh ( 67,43 Eur)
A37: **** Apkures patēriņa daļas sadalījuma % atkarīgs no vidējās mēneša temperatūras
A42: Rēķins sagatavots elektroniski un derīgs bez paraksta

Sheet dz3
A2: =TODAY() -> 46135 | E2: =_xlfn.TEXTJOIN("",TRUE,"Rēķins Nr. B",Rēķini!A1,Rēķini!D2,"0",Rekvizīti!C3+2) -> Rēķins Nr. B2026040438
A4: Piegādātājs: Dzīvokļu īpašnieku biedrība "Brīvības 166" | E4: Saņēmējs: Ligita Loeve
A5: Jur. Adrese: Brīvības 166-4, Rīga | E5: Adrese: Brīvības 166-3, Rīga LV-1012
A6: Reģ. nr. 40008324442
A7: “Swedbank” AS, SWIFT: HABALV22
A8: Konts: LV43HABA0551054594820
A10: =_xlfn.TEXTJOIN("",TRUE,"Komunālo pakalpojumu sniegšanas periods: ","2025. gada ",Rēķini!$D$1) -> Komunālo pakalpojumu sniegšanas periods: 2025. gada MARTS
A11: =_xlfn.TEXTJOIN("",TRUE,"Apsaimniekošana, remontdarbu fonds: ",Rēķini!$A$1,". gada ",Rēķini!$E$1) -> Apsaimniekošana, remontdarbu fonds: 2026. gada APRĪLIS
A13: Rēķina apmaksas termiņš: | B13: =DATE(Rēķini!A1,Rēķini!$D$2,30) -> 46142
A15: Nosaukums | D15: Mērvien. | E15: Daudz. | F15: Cena (EUR) | G15: Summa (EUR)
A17: Apsaimniekošana | D17: m2 | E17: 111.1 | F17: 0.6044 | G17: =ROUND(E17*F17,2) -> 67.15
A18: Remontdarbu fonds | D18: m2 | E18: 111.1 | F18: 0.3156 | G18: =ROUND(E18*F18,2) -> 35.06
A19: Ūdens apgāde un kanalizācija
A20: =_xlfn.TEXTJOIN(" ",TRUE,"Aukstā ūdens skaitītājs virt. (rād:",Ūdens!J4,"-", Ūdens!K4, ")") -> Aukstā ūdens skaitītājs virt. (rād: 0,77 - 1,29 ) | D20: m3 | E20: =Ūdens!R4 -> 0.52 | F20: =Rēķini!G2 -> 3.2307 | G20: =Ūdens!X4 -> 1.68
A21: =_xlfn.TEXTJOIN(" ",TRUE,"Karstā ūdens skaitītājs virt. (rād:",Ūdens!L4,"-", Ūdens!M4, ")") -> Karstā ūdens skaitītājs virt. (rād: 0,25 - 0,31 ) | D21: m3 | E21: =Ūdens!S4 -> 0.06 | F21: =Rēķini!H2 -> 6.9107 | G21: =Ūdens!Y4 -> 0.41
A22: =_xlfn.TEXTJOIN(" ",TRUE,"Aukstā ūdens skaitītājs WC (rād:",Ūdens!N4,"-", Ūdens!O4, ")") -> Aukstā ūdens skaitītājs WC (rād: 0,01 - 0,06 ) | D22: m3 | E22: =Ūdens!T4 -> 0.05 | F22: =Rēķini!G2 -> 3.2307 | G22: =Ūdens!Z4 -> 0.16
A23: =_xlfn.TEXTJOIN(" ",TRUE,"Karstā ūdens skaitītājs WC (rād:",Ūdens!P4,"-", Ūdens!Q4, ")") -> Karstā ūdens skaitītājs WC (rād: 0,07 - 0,15 ) | D23: m3 | E23: =Ūdens!U4 -> 0.08 | F23: =Rēķini!H2 -> 6.9107 | G23: =Ūdens!AA4 -> 0.55
A24: Cirkulācija* | D24: dzīvoklis | E24: 1 | F24: =Rēķini!I7 -> 16.92 | G24: =Rēķini!I7 -> 16.92
A25: Lietus notekūdeņi | D25: mēnesis | E25: 1 | F25: =Rēķini!J7 -> 0.8 | G25: =Rēķini!J7 -> 0.8
A26: Atkritumu izvešana** | D26: iedz. | E26: 1 | F26: =Rēķini!K2 -> 7.11 | G26: =E26*F26 -> 7.11
A27: Koplietošanas elektrība*** | D27: dzīvoklis | E27: 1 | F27: =Rēķini!L7 -> 5.62 | G27: =Rēķini!L7 -> 5.62
A28: Apkure (kopējā) 40% | D28: m2 | E28: 111.1 | F28: =Rekvizīti!C33 -> 0.2476 | G28: =Rēķini!M7 -> 27.51
A29: Apkure (patēriņš) 60% **** | D29: vienības | E29: 530.082 | F29: =Rekvizīti!C34 -> 0.0975 | G29: =Rēķini!N7 -> 51.68
A30: Siltummezgla apkalpošana | D30: m2 | E30: 111.1 | F30: =Rēķini!O2 -> 0.037 | G30: =Rēķini!O7 -> 4.11
D31: Summa, EUR | G31: =SUM(G17:G30) -> 218.76
D32: Parāds: | G32: =Rēķini!R7 -> 0
D33: Summa samaksai kopā: | G33: =G31+G32 -> 218.76
A35: =_xlfn.TEXTJOIN(" ",TRUE,"Summa vārdiem: ",Rēķini!U7) -> Summa vārdiem: Divi simti astoņpadsmit eiro, 76 centi
A38: =_xlfn.TEXTJOIN(" ",TRUE,"* Siltumenerģijas patēriņš", Rēķini!$D$30, "kopā: ",Rekvizīti!$C$19,"Mwh (",Rēķini!$E$32, "Eur)") -> * Siltumenerģijas patēriņš martā kopā: 7,81 Mwh ( 729,3 Eur)
A39: =_xlfn.TEXTJOIN(" ",TRUE,"** Atkritumu izvešana kopā:",Rēķini!$E$33,"EUR(1x nedēļā), aprēķināts uz 16 iedzīvotājiem") -> ** Atkritumu izvešana kopā: 113,72 EUR(1x nedēļā), aprēķināts uz 16 iedzīvotājiem
A40: =_xlfn.TEXTJOIN(" ",TRUE,"*** Koplietošanas elektrības patēriņš", Rēķini!$D$30, "kopā: ",Rekvizīti!$C$20,"Kwh (", Rekvizīti!$C$9, "Eur)") -> *** Koplietošanas elektrības patēriņš martā kopā: 278,46 Kwh ( 67,43 Eur)
A41: **** Apkures patēriņa daļas sadalījuma % atkarīgs no vidējās mēneša temperatūras
A42: ***** Saskaņā ar 11.06.2025. balsojumu
A46: Rēķins sagatavots elektroniski un derīgs bez paraksta

Sheet dz4
A2: =TODAY() -> 46135 | E2: =_xlfn.TEXTJOIN("",TRUE,"Rēķins Nr. B",Rēķini!A1,Rēķini!D2,"0",Rekvizīti!C3+3) -> Rēķins Nr. B2026040439
A4: Piegādātājs: Dzīvokļu īpašnieku biedrība "Brīvības 166" | E4: Saņēmējs: Hedija Butina
A5: Jur. Adrese: Brīvības 166-4, Rīga | E5: Adrese: Brīvības 166-4, Rīga LV-1012
A6: Reģ. nr. 40008324442
A7: “Swedbank” AS, SWIFT: HABALV22
A8: Konts: LV43HABA0551054594820
A10: =_xlfn.TEXTJOIN("",TRUE,"Komunālo pakalpojumu sniegšanas periods: ","2025. gada ",Rēķini!$D$1) -> Komunālo pakalpojumu sniegšanas periods: 2025. gada MARTS
A11: =_xlfn.TEXTJOIN("",TRUE,"Apsaimniekošana: ",Rēķini!$A$1,". gada ",Rēķini!$E$1) -> Apsaimniekošana: 2026. gada APRĪLIS
A13: Rēķina apmaksas termiņš: | B13: =DATE(Rēķini!A1,Rēķini!$D$2,30) -> 46142
A15: Nosaukums | D15: Mērvien. | E15: Daudz. | F15: Cena (EUR) | G15: Summa (EUR)
A17: Apsaimniekošana | D17: m2 | E17: 109.4 | F17: 0.6044 | G17: =ROUND(E17*F17,2) -> 66.12
A18: Ūdens apgāde un kanalizācija
A19: =_xlfn.TEXTJOIN(" ",TRUE,"Aukstā ūdens skaitītājs WC. (rād:",Ūdens!J5,"-", Ūdens!K5, ")") -> Aukstā ūdens skaitītājs WC. (rād: 12,34 - 15,8 ) | D19: m3 | E19: =Ūdens!R5 -> 3.46 | F19: =Rēķini!G2 -> 3.2307 | G19: =Ūdens!X5 -> 11.18
A20: =_xlfn.TEXTJOIN(" ",TRUE,"Karstā ūdens skaitītājs WC (rād:",Ūdens!L5,"-", Ūdens!M5, ")") -> Karstā ūdens skaitītājs WC (rād: 5,36 - 7,01 ) | D20: m3 | E20: =Ūdens!S5 -> 1.65 | F20: =Rēķini!H2 -> 6.9107 | G20: =Ūdens!Y5 -> 11.4
A21: =_xlfn.TEXTJOIN(" ",TRUE,"Aukstā ūdens skaitītājs virt. (rād:",Ūdens!N5,"-", Ūdens!O5, ")") -> Aukstā ūdens skaitītājs virt. (rād: 1,45 - 1,78 ) | D21: m3 | E21: =Ūdens!T5 -> 0.33 | F21: =Rēķini!G2 -> 3.2307 | G21: =Ūdens!Z5 -> 1.07
A22: =_xlfn.TEXTJOIN(" ",TRUE,"Karstā ūdens skaitītājs virt. (rād:",Ūdens!P5,"-", Ūdens!Q5, ")") -> Karstā ūdens skaitītājs virt. (rād: 4,06 - 5,06 ) | D22: m3 | E22: =Ūdens!U5 -> 1 | F22: =Rēķini!H2 -> 6.9107 | G22: =Ūdens!AA5 -> 6.91
A23: Cirkulācija* | D23: dzīvoklis | E23: 1 | F23: =Rēķini!I8 -> 16.92 | G23: =Rēķini!I8 -> 16.92
A24: Lietus notekūdeņi | D24: mēnesis | E24: 1 | F24: =Rēķini!J8 -> 0.8 | G24: =Rēķini!J8 -> 0.8
A25: Atkritumu izvešana** | D25: iedz. | E25: 2 | F25: =Rēķini!K2 -> 7.11 | G25: =E25*F25 -> 14.22
A26: Koplietošanas elektrība*** | D26: dzīvoklis | E26: 1 | F26: =Rēķini!L8 -> 5.62 | G26: =Rēķini!L8 -> 5.62
A27: Apkure (kopējā) 40% | D27: m2 | E27: 109.4 | F27: =Rekvizīti!C33 -> 0.2476 | G27: =Rēķini!M8 -> 27.09
A28: Apkure (patēriņš) 60% **** | D28: vienības | E28: 511.854 | F28: =Rekvizīti!C34 -> 0.0975 | G28: =Rēķini!N8 -> 49.91
A29: Siltummezgla apkalpošana | D29: m2 | E29: 109.4 | F29: =Rēķini!O2 -> 0.037 | G29: =Rēķini!O8 -> 4.05
A30: Apsaimniekošanas atlaide | G30: =Rēķini!Q8 -> -100.17
D31: Summa samaksai, EUR | G31: =SUM(G17:G30) -> 115.12
A33: =_xlfn.TEXTJOIN(" ",TRUE,"Summa vārdiem: ",Rēķini!U8) -> Summa vārdiem: Viens simts piecpadsmit eiro, 12 centi
A36: =_xlfn.TEXTJOIN(" ",TRUE,"* Siltumenerģijas patēriņš", Rēķini!$D$30, "kopā: ",Rekvizīti!$C$19,"Mwh (",Rēķini!$E$32, "Eur)") -> * Siltumenerģijas patēriņš martā kopā: 7,81 Mwh ( 729,3 Eur)
A37: =_xlfn.TEXTJOIN(" ",TRUE,"** Atkritumu izvešana kopā:",Rēķini!$E$33,"EUR(1x nedēļā), aprēķināts uz 16 iedzīvotājiem") -> ** Atkritumu izvešana kopā: 113,72 EUR(1x nedēļā), aprēķināts uz 16 iedzīvotājiem
A38: =_xlfn.TEXTJOIN(" ",TRUE,"*** Koplietošanas elektrības patēriņš", Rēķini!$D$30, "kopā: ",Rekvizīti!$C$20,"Kwh (", Rekvizīti!$C$9, "Eur)") -> *** Koplietošanas elektrības patēriņš martā kopā: 278,46 Kwh ( 67,43 Eur)
A39: **** Apkures patēriņa daļas sadalījuma % atkarīgs no vidējās mēneša temperatūras
A45: Rēķins sagatavots elektroniski un derīgs bez paraksta

Sheet dz6
A2: =TODAY() -> 46135 | E2: =_xlfn.TEXTJOIN("",TRUE,"Rēķins Nr. B",Rēķini!A1,Rēķini!D2,"0",Rekvizīti!C3+4) -> Rēķins Nr. B2026040440
A4: Piegādātājs: Dzīvokļu īpašnieku biedrība "Brīvības 166" | E4: Saņēmējs: Ilze Butina
A5: Jur. Adrese: Brīvības 166-4, Rīga | E5: Adrese: Brīvības 166-6, Rīga LV-1012
A6: Reģ. nr. 40008324442
A7: “Swedbank” AS, SWIFT: HABALV22
A8: Konts: LV43HABA0551054594820
A10: =_xlfn.TEXTJOIN("",TRUE,"Komunālo pakalpojumu sniegšanas periods: ","2025. gada ",Rēķini!$D$1) -> Komunālo pakalpojumu sniegšanas periods: 2025. gada MARTS
A11: =_xlfn.TEXTJOIN("",TRUE,"Apsaimniekošana: ",Rēķini!$A$1,". gada ",Rēķini!$E$1) -> Apsaimniekošana: 2026. gada APRĪLIS
A13: Rēķina apmaksas termiņš: | B13: =DATE(Rēķini!A1,Rēķini!$D$2,30) -> 46142
A15: Nosaukums | D15: Mērvien. | E15: Daudz. | F15: Cena (EUR) | G15: Summa (EUR)
A17: Apsaimniekošana | D17: m2 | E17: 28.4 | F17: 0.6044 | G17: =E17*F17 -> 17.16496
A18: Ūdens apgāde un kanalizācija
A19: =_xlfn.TEXTJOIN(" ",TRUE,"Aukstā ūdens skaitītājs (rād:",Ūdens!J6,"-", Ūdens!K6, ")") -> Aukstā ūdens skaitītājs (rād: 0,26 - 0,31 ) | D19: m3 | E19: =Ūdens!R5 -> 3.46 | F19: =Rēķini!G2 -> 3.2307 | G19: =Ūdens!X6 -> 0.16
A20: =_xlfn.TEXTJOIN(" ",TRUE,"Karstā ūdens skaitītājs (rād:",Ūdens!L6,"-", Ūdens!M6, ")") -> Karstā ūdens skaitītājs (rād: 0,16 - 0,2 ) | D20: m3 | E20: =Ūdens!S6 -> 0.04 | F20: =Rēķini!H2 -> 6.9107 | G20: =Ūdens!Y6 -> 0.28
A21: Cirkulācija* | D21: dzīvoklis | E21: 1 | F21: =Rēķini!I9 -> 6.77 | G21: =Rēķini!I9 -> 6.77
A22: Lietus notekūdeņi | D22: mēnesis | E22: 1 | F22: =Rēķini!J9 -> 0.8 | G22: =Rēķini!J9 -> 0.8
A23: Atkritumu izvešana** | D23: iedz. | E23: 0 | F23: =Rēķini!K2 -> 7.11 | G23: =E23*F23 -> 0
A24: Koplietošanas elektrība*** | D24: dzīvoklis | E24: 1 | F24: =Rēķini!L9 -> 5.62 | G24: =Rēķini!L9 -> 5.62
A25: Apkure (kopējā) 40% | D25: m2 | E25: 28.4 | F25: =Rekvizīti!C33 -> 0.2476 | G25: =Rēķini!M9 -> 7.03
A26: Apkure (patēriņš) 60% **** | D26: vienības | E26: 0 | F26: =Rekvizīti!C34 -> 0.0975 | G26: =Rēķini!N9 -> 0
A27: Siltummezgla apkalpošana | D27: m2 | E27: 28.4 | F27: =Rēķini!O2 -> 0.037 | G27: =Rēķini!O9 -> 1.05
A28: Apsaimniekošanas atlaide | G28: =Rēķini!Q9 -> -18.21496
D29: Summa samaksai, EUR | G29: =SUM(G17:G28) -> 20.66
A31: =_xlfn.TEXTJOIN(" ",TRUE,"Summa vārdiem: ",Rēķini!U9) -> Summa vārdiem: Divdesmit eiro, 66 centi
A34: =_xlfn.TEXTJOIN(" ",TRUE,"* Siltumenerģijas patēriņš", Rēķini!$D$30, "kopā: ",Rekvizīti!$C$19,"Mwh (",Rēķini!$E$32, "Eur)") -> * Siltumenerģijas patēriņš martā kopā: 7,81 Mwh ( 729,3 Eur)
A35: =_xlfn.TEXTJOIN(" ",TRUE,"** Atkritumu izvešana kopā:",Rēķini!$E$33,"EUR(1x nedēļā), aprēķināts uz 16 iedzīvotājiem") -> ** Atkritumu izvešana kopā: 113,72 EUR(1x nedēļā), aprēķināts uz 16 iedzīvotājiem
A36: =_xlfn.TEXTJOIN(" ",TRUE,"*** Koplietošanas elektrības patēriņš", Rēķini!$D$30, "kopā: ",Rekvizīti!$C$20,"Kwh (", Rekvizīti!$C$9, "Eur)") -> *** Koplietošanas elektrības patēriņš martā kopā: 278,46 Kwh ( 67,43 Eur)
A37: **** Apkures patēriņa daļas sadalījuma % atkarīgs no vidējās mēneša temperatūras
A43: Rēķins sagatavots elektroniski un derīgs bez paraksta

Sheet dz7
A2: =TODAY() -> 46135 | E2: =_xlfn.TEXTJOIN("",TRUE,"Rēķins Nr. B",Rēķini!A1,Rēķini!D2,"0",Rekvizīti!C3+5) -> Rēķins Nr. B2026040441
A4: Piegādātājs: Dzīvokļu īpašnieku biedrība "Brīvības 166" | E4: Saņēmējs: Hedija Butina
A5: Jur. Adrese: Brīvības 166-4, Rīga | E5: Adrese: Brīvības 166-7, Rīga LV-1012
A6: Reģ. nr. 40008324442
A7: “Swedbank” AS, SWIFT: HABALV22
A8: Konts: LV43HABA0551054594820
A10: =_xlfn.TEXTJOIN("",TRUE,"Komunālo pakalpojumu sniegšanas periods: ","2025. gada ",Rēķini!$D$1) -> Komunālo pakalpojumu sniegšanas periods: 2025. gada MARTS
A11: =_xlfn.TEXTJOIN("",TRUE,"Apsaimniekošana: ",Rēķini!$A$1,". gada ",Rēķini!$E$1) -> Apsaimniekošana: 2026. gada APRĪLIS
A13: Rēķina apmaksas termiņš: | B13: =DATE(Rēķini!A1,Rēķini!$D$2,30) -> 46142
A15: Nosaukums | D15: Mērvien. | E15: Daudz. | F15: Cena (EUR) | G15: Summa (EUR)
A17: Apsaimniekošana | D17: m2 | E17: 84.7 | F17: 0.6044 | G17: =E17*F17 -> 51.19268
A18: Ūdens apgāde un kanalizācija
A19: =_xlfn.TEXTJOIN(" ",TRUE,"Aukstā ūdens skaitītājs vanna (rād:",Ūdens!J7,"-", Ūdens!K7, ")") -> Aukstā ūdens skaitītājs vanna (rād: 12,97 - 15,83 ) | D19: m3 | E19: =Ūdens!R7 -> 2.86 | F19: =Rēķini!G2 -> 3.2307 | G19: =Ūdens!X7 -> 9.24
A20: =_xlfn.TEXTJOIN(" ",TRUE,"Karstā ūdens skaitītājs vanna (rād:",Ūdens!L7,"-", Ūdens!M7, ")") -> Karstā ūdens skaitītājs vanna (rād: 12,51 - 15,11 ) | D20: m3 | E20: =Ūdens!S7 -> 2.6 | F20: =Rēķini!H2 -> 6.9107 | G20: =Ūdens!Y7 -> 17.97
A21: =_xlfn.TEXTJOIN(" ",TRUE,"Aukstā ūdens skaitītājs WC (rād:",Ūdens!N7,"-", Ūdens!O7, ")") -> Aukstā ūdens skaitītājs WC (rād: 11,81 - 14,52 ) | D21: m3 | E21: =Ūdens!T7 -> 2.71 | F21: =Rēķini!G2 -> 3.2307 | G21: =Ūdens!Z7 -> 8.76
A22: =_xlfn.TEXTJOIN(" ",TRUE,"Karstā ūdens skaitītājs WC (rād:",Ūdens!P7,"-", Ūdens!Q7, ")") -> Karstā ūdens skaitītājs WC (rād: 4,26 - 5,07 ) | D22: m3 | E22: =Ūdens!U7 -> 0.81 | F22: =Rēķini!H2 -> 6.9107 | G22: =Ūdens!AA7 -> 5.6
A23: Cirkulācija* | D23: dzīvoklis | E23: 1 | F23: =Rēķini!I10 -> 13.54 | G23: =Rēķini!I10 -> 13.54
A24: Lietus notekūdeņi | D24: mēnesis | E24: 1 | F24: =Rēķini!J10 -> 0.8 | G24: =Rēķini!J10 -> 0.8
A25: Atkritumu izvešana** | D25: iedz. | E25: 3 | F25: =Rēķini!K2 -> 7.11 | G25: =E25*F25 -> 21.33
A26: Koplietošanas elektrība*** | D26: dzīvoklis | E26: 1 | F26: =Rēķini!L10 -> 5.62 | G26: =Rēķini!L10 -> 5.62
A27: Apkure (kopējā) 40% | D27: m2 | E27: 84.7 | F27: =Rekvizīti!C33 -> 0.2476 | G27: =Rēķini!M10 -> 20.98
A28: Apkure (patēriņš) 60% **** | D28: vienības | E28: 369.411 | F28: =Rekvizīti!C34 -> 0.0975 | G28: =Rēķini!N10 -> 36.02
A29: Siltummezgla apkalpošana | D29: m2 | E29: 84.7 | F29: =Rēķini!$O$2 -> 0.037 | G29: =Rēķini!$O$10 -> 3.13
A30: Apsaimniekošanas atlaide | G30: =Rēķini!Q10 -> -75.55
D31: Summa samaksai, EUR | G31: =SUM(G17:G30) -> 118.63268
F32: Avanss | G32: 0.78
F33: Kopā samaksai, EUR | G33: =G31-G32 -> 117.85268
A37: =_xlfn.TEXTJOIN(" ",TRUE,"Summa vārdiem: ",Rēķini!U10) -> Summa vārdiem: Viens simts astoņpadsmit eiro, 63 centi
A40: =_xlfn.TEXTJOIN(" ",TRUE,"* Siltumenerģijas patēriņš", Rēķini!$D$30, "kopā: ",Rekvizīti!$C$19,"Mwh (",Rēķini!$E$32, "Eur)") -> * Siltumenerģijas patēriņš martā kopā: 7,81 Mwh ( 729,3 Eur)
A41: =_xlfn.TEXTJOIN(" ",TRUE,"** Atkritumu izvešana kopā:",Rēķini!$E$33,"EUR(1x nedēļā), aprēķināts uz 16 iedzīvotājiem") -> ** Atkritumu izvešana kopā: 113,72 EUR(1x nedēļā), aprēķināts uz 16 iedzīvotājiem
A42: =_xlfn.TEXTJOIN(" ",TRUE,"*** Koplietošanas elektrības patēriņš", Rēķini!$D$30, "kopā: ",Rekvizīti!$C$20,"Kwh (", Rekvizīti!$C$9, "Eur)") -> *** Koplietošanas elektrības patēriņš martā kopā: 278,46 Kwh ( 67,43 Eur)
A43: **** Apkures patēriņa daļas sadalījuma % atkarīgs no vidējās mēneša temperatūras
A49: Rēķins sagatavots elektroniski un derīgs bez paraksta

Sheet dz8
A2: =TODAY() -> 46135 | D2: =_xlfn.TEXTJOIN("",TRUE,"Rēķins Nr. B",Rēķini!A1,Rēķini!D2,"0",Rekvizīti!C3+6) -> Rēķins Nr. B2026040442
A4: Piegādātājs: Dzīvokļu īpašnieku biedrība "Brīvības 166" | D4: Saņēmējs: | E4: Zane Butina
A5: Jur. Adrese: Brīvības 166-4, Rīga | D5: Adrese: Brīvības 166-8, Rīga LV-1012
A6: Reģ. nr. 40008324442
A7: “Swedbank” AS, SWIFT: HABALV22
A8: Konts: LV43HABA0551054594820
A10: =_xlfn.TEXTJOIN("",TRUE,"Komunālo pakalpojumu sniegšanas periods: ","2026. gada ",Rēķini!$D$1) -> Komunālo pakalpojumu sniegšanas periods: 2026. gada MARTS
A11: =_xlfn.TEXTJOIN("",TRUE,"Apsaimniekošana: ",Rēķini!$A$1,". gada ",Rēķini!$E$1) -> Apsaimniekošana: 2026. gada APRĪLIS
A13: Rēķina apmaksas termiņš: | B13: =DATE(Rēķini!A1,Rēķini!$D$2,30) -> 46142
A16: Nosaukums | D16: Mērvien. | E16: Daudz. | F16: Cena (EUR) | G16: Summa (EUR)
A18: Apsaimniekošana | D18: m2 | E18: 47.8 | F18: 0.6044 | G18: =ROUND(E18*F18,2) -> 28.89
A19: Ūdens apgāde un kanalizācija
A20: =_xlfn.TEXTJOIN(" ",TRUE,"Aukstā ūdens skaitītājs (rād:",Ūdens!J8,"-", Ūdens!K8, ")") -> Aukstā ūdens skaitītājs (rād: 32,34 - 39,02 ) | D20: m3 | E20: =Ūdens!R8 -> 6.68 | F20: =Rēķini!G2 -> 3.2307 | G20: =ROUND(Ūdens!X8,2) -> 21.58
A21: =_xlfn.TEXTJOIN(" ",TRUE,"Karstā ūdens skaitītājs (rād:",Ūdens!L8,"-", Ūdens!M8, ")") -> Karstā ūdens skaitītājs (rād: 18,35 - 22,22 ) | D21: m3 | E21: =Ūdens!S8 -> 3.87 | F21: =Rēķini!H2 -> 6.9107 | G21: =ROUND(Ūdens!Y8,2) -> 26.74
A22: Cirkulācija* | D22: dzīvoklis | E22: 1 | F22: =Rēķini!I11 -> 6.77 | G22: =Rēķini!I11 -> 6.77
A23: Lietus notekūdeņi | D23: mēnesis | E23: 1 | F23: =Rēķini!J11 -> 0.8 | G23: =Rēķini!J11 -> 0.8
A24: Atkritumu izvešana** | D24: iedz. | E24: 2 | F24: =Rēķini!K2 -> 7.11 | G24: =F24*E24 -> 14.22
A25: Koplietošanas elektrība*** | D25: dzīvoklis | E25: 1 | F25: =Rēķini!L1 -> 5.62 | G25: =Rēķini!L11 -> 5.62
A26: Apkure (kopējā) 40% | D26: m2 | E26: 47.8 | F26: =Rekvizīti!C33 -> 0.2476 | G26: =Rēķini!M11 -> 11.84
A27: Apkure (patēriņš) 60% **** | D27: vienības | E27: 80.85 | F27: =Rekvizīti!C34 -> 0.0975 | G27: =Rēķini!N11 -> 7.88
A28: Siltummezgla apkalpošana | D28: m2 | E28: 47.8 | F28: =Rēķini!$O$2 -> 0.037 | G28: =Rēķini!$O$11 -> 1.77
A29: Apsaimniekošanas atlaide | G29: =Rēķini!Q11 -> -30.66
D30: Summa, EUR | G30: =SUM(G18:G29) -> 95.45
A34: =_xlfn.TEXTJOIN(" ",TRUE,"Summa vārdiem: ",Rēķini!U11) -> Summa vārdiem: Deviņdesmit pieci eiro, 45 centi
A37: =_xlfn.TEXTJOIN(" ",TRUE,"* Siltumenerģijas patēriņš", Rēķini!$D$30, "kopā: ",Rekvizīti!$C$19,"Mwh (",Rēķini!$E$32, "Eur)") -> * Siltumenerģijas patēriņš martā kopā: 7,81 Mwh ( 729,3 Eur)
A38: =_xlfn.TEXTJOIN(" ",TRUE,"** Atkritumu izvešana kopā:",Rēķini!$E$33,"EUR(1x nedēļā), aprēķināts uz 16 iedzīvotājiem") -> ** Atkritumu izvešana kopā: 113,72 EUR(1x nedēļā), aprēķināts uz 16 iedzīvotājiem
A39: =_xlfn.TEXTJOIN(" ",TRUE,"*** Koplietošanas elektrības patēriņš", Rēķini!$D$30, "kopā: ",Rekvizīti!$C$20,"Kwh (", Rekvizīti!$C$9, "Eur)") -> *** Koplietošanas elektrības patēriņš martā kopā: 278,46 Kwh ( 67,43 Eur)
A40: **** Apkures patēriņa daļas sadalījuma % atkarīgs no vidējās mēneša temperatūras
A45: Rēķins sagatavots elektroniski un derīgs bez paraksta

Sheet dz9
A2: =TODAY() -> 46135 | E2: =_xlfn.TEXTJOIN("",TRUE,"Rēķins Nr. B",Rēķini!A1,Rēķini!D2,"0",Rekvizīti!C3+7) -> Rēķins Nr. B2026040443
A4: Piegādātājs: Dzīvokļu īpašnieku biedrība "Brīvības 166" | E4: Saņēmējs: Zane Butina
A5: Jur. Adrese: Brīvības 166-4, Rīga | E5: Adrese: Brīvības 166-9, Rīga LV-1012
A6: Reģ. nr. 40008324442
A7: “Swedbank” AS, SWIFT: HABALV22
A8: Konts: LV43HABA0551054594820
A10: =_xlfn.TEXTJOIN("",TRUE,"Komunālo pakalpojumu sniegšanas periods: ","2025. gada ",Rēķini!$D$1) -> Komunālo pakalpojumu sniegšanas periods: 2025. gada MARTS
A11: =_xlfn.TEXTJOIN("",TRUE,"Apsaimniekošana: ",Rēķini!$A$1,". gada ",Rēķini!$E$1) -> Apsaimniekošana: 2026. gada APRĪLIS
A14: Rēķina apmaksas termiņš: | B14: =DATE(Rēķini!A1,Rēķini!$D$2,30) -> 46142
A16: Nosaukums | D16: Mērvien. | E16: Daudz. | F16: Cena (EUR) | G16: Summa (EUR)
A18: Apsaimniekošana | D18: m2 | E18: 65.7 | F18: 0.6044 | G18: =ROUND(E18*F18,2) -> 39.71
A19: Ūdens apgāde un kanalizācija
A20: =_xlfn.TEXTJOIN(" ",TRUE,"Aukstā ūdens skaitītājs kor. (rād:",Ūdens!J9,"-", Ūdens!K9, ")") -> Aukstā ūdens skaitītājs kor. (rād: 0,17 - 0,17 ) | D20: m3 | E20: =Ūdens!R9 -> 0 | F20: =Rēķini!G2 -> 3.2307 | G20: =Ūdens!X9 -> 0
A21: =_xlfn.TEXTJOIN(" ",TRUE,"Karstā ūdens skaitītājs kor. (rād:",Ūdens!L9,"-", Ūdens!M9, ")") -> Karstā ūdens skaitītājs kor. (rād: 0,63 - 0,63 ) | D21: m3 | E21: =Ūdens!S9 -> 0 | F21: =Rēķini!H2 -> 6.9107 | G21: =Ūdens!Y9 -> 0
A22: =_xlfn.TEXTJOIN(" ",TRUE,"Aukstā ūdens skaitītājs vanna (rād:",Ūdens!N9,"-", Ūdens!O9, ")") -> Aukstā ūdens skaitītājs vanna (rād: 1,35 - 1,35 ) | D22: m3 | E22: =Ūdens!T9 -> 0 | F22: =Rēķini!G2 -> 3.2307 | G22: =Ūdens!Z9 -> 0
A23: =_xlfn.TEXTJOIN(" ",TRUE,"Karstā ūdens skaitītājs vanna (rād:",Ūdens!P9,"-", Ūdens!Q9, ")") -> Karstā ūdens skaitītājs vanna (rād: 0,11 - 0,11 ) | D23: m3 | E23: =Ūdens!U9 -> 0 | F23: =Rēķini!H2 -> 6.9107 | G23: =Ūdens!AA9 -> 0
A24: Cirkulācija* | D24: dzīvoklis | E24: 1 | F24: =Rēķini!I12 -> 13.54 | G24: =Rēķini!I12 -> 13.54
A25: Lietus notekūdeņi | D25: mēnesis | E25: 1 | F25: =Rēķini!J12 -> 0.8 | G25: =Rēķini!J12 -> 0.8
A26: Atkritumu izvešana** | D26: iedz. | E26: 1 | F26: =Rēķini!K2 -> 7.11 | G26: =E26*F26 -> 7.11
A27: Koplietošanas elektrība*** | D27: dzīvoklis | E27: 1 | F27: =Rēķini!L12 -> 5.62 | G27: =Rēķini!L12 -> 5.62
A28: Apkure (kopējā) 40% | D28: m2 | E28: 65.7 | F28: =Rekvizīti!C33 -> 0.2476 | G28: =Rēķini!M12 -> 16.27
A29: Apkure (patēriņš) 60% **** | D29: vienības | E29: 0 | F29: =Rekvizīti!C34 -> 0.0975 | G29: =Rēķini!N12 -> 0
A30: Siltummezgla apkalpošana | D30: m2 | E30: 65.7 | F30: =Rēķini!$O$2 -> 0.037 | G30: =Rēķini!$O$12 -> 2.43
A31: Apsaimniekošanas atlaide | G31: =Rēķini!Q12 -> -42.13908
D32: Summa samaksai, EUR | G32: =SUM(G18:G31) -> 43.34092
A34: =_xlfn.TEXTJOIN(" ",TRUE,"Summa vārdiem: ",Rēķini!U12) -> Summa vārdiem: Četrdesmit trīs eiro, 34 centi
A37: =_xlfn.TEXTJOIN(" ",TRUE,"* Siltumenerģijas patēriņš", Rēķini!$D$30, "kopā: ",Rekvizīti!$C$19,"Mwh (",Rēķini!$E$32, "Eur)") -> * Siltumenerģijas patēriņš martā kopā: 7,81 Mwh ( 729,3 Eur)
A38: =_xlfn.TEXTJOIN(" ",TRUE,"** Atkritumu izvešana kopā:",Rēķini!$E$33,"EUR(1x nedēļā), aprēķināts uz 16 iedzīvotājiem") -> ** Atkritumu izvešana kopā: 113,72 EUR(1x nedēļā), aprēķināts uz 16 iedzīvotājiem
A39: =_xlfn.TEXTJOIN(" ",TRUE,"*** Koplietošanas elektrības patēriņš", Rēķini!$D$30, "kopā: ",Rekvizīti!$C$20,"Kwh (", Rekvizīti!$C$9, "Eur)") -> *** Koplietošanas elektrības patēriņš martā kopā: 278,46 Kwh ( 67,43 Eur)
A40: **** Apkures patēriņa daļas sadalījuma % atkarīgs no vidējās mēneša temperatūras
A45: Rēķins sagatavots elektroniski un derīgs bez paraksta

Sheet dz10
A2: =TODAY() -> 46135 | E2: =_xlfn.TEXTJOIN("",TRUE,"Rēķins Nr. B",Rēķini!A1, Rēķini!D2,"0",Rekvizīti!C3+8) -> Rēķins Nr. B2026040444
A4: Piegādātājs: Dzīvokļu īpašnieku biedrība "Brīvības 166" | E4: Saņēmējs: Ilze Butina
A5: Jur. Adrese: Brīvības 166-4, Rīga | E5: Adrese: Brīvības 166-10, Rīga LV-1012
A6: Reģ. nr. 40008324442
A7: “Swedbank” AS, SWIFT: HABALV22
A8: Konts: LV43HABA0551054594820
A10: =_xlfn.TEXTJOIN("",TRUE,"Komunālo pakalpojumu sniegšanas periods: ","2025. gada ",Rēķini!$D$1) -> Komunālo pakalpojumu sniegšanas periods: 2025. gada MARTS
A11: =_xlfn.TEXTJOIN("",TRUE,"Apsaimniekošana: ",Rēķini!$A$1,". gada ",Rēķini!$E$1) -> Apsaimniekošana: 2026. gada APRĪLIS
A13: Rēķina apmaksas termiņš: | B13: =DATE(Rēķini!A1,Rēķini!$D$2,30) -> 46142
A15: Nosaukums | D15: Mērvien. | E15: Daudz. | F15: Cena (EUR) | G15: Summa (EUR)
A17: Apsaimniekošana | D17: m2 | E17: 47.1 | F17: 0.6044 | G17: =ROUND(E17*F17,2) -> 28.47
A18: Ūdens apgāde un kanalizācija
A19: =_xlfn.TEXTJOIN(" ",TRUE,"Aukstā ūdens skaitītājs (rād:",Ūdens!J10,"-", Ūdens!K10, ")") -> Aukstā ūdens skaitītājs (rād: 9,86 - 13,01 ) | D19: m3 | E19: =Ūdens!R10 -> 3.15 | F19: =Rēķini!G2 -> 3.2307 | G19: =ROUND(Ūdens!X10,2) -> 10.18
A20: =_xlfn.TEXTJOIN(" ",TRUE,"Karstā ūdens skaitītājs (rād:",Ūdens!L10,"-", Ūdens!M10, ")") -> Karstā ūdens skaitītājs (rād: 12,03 - 15,6 ) | D20: m3 | E20: =Ūdens!S10 -> 3.57 | F20: =Rēķini!H2 -> 6.9107 | G20: =ROUND(Ūdens!Y10,2) -> 24.67
A21: Cirkulācija* | D21: dzīvoklis | E21: 1 | F21: =Rēķini!I13 -> 6.77 | G21: =Rēķini!I13 -> 6.77
A22: Lietus notekūdeņi | D22: mēnesis | E22: 1 | F22: =Rēķini!J13 -> 0.8 | G22: =Rēķini!J13 -> 0.8
A23: Atkritumu izvešana** | D23: iedz. | E23: 1 | F23: =Rēķini!K2 -> 7.11 | G23: =E23*F23 -> 7.11
A24: Koplietošanas elektrība*** | D24: dzīvoklis | E24: 1 | F24: =Rēķini!L13 -> 5.62 | G24: =Rēķini!L13 -> 5.62
A25: Apkure (kopējā) 40% | D25: m2 | E25: 47.1 | F25: =Rekvizīti!C33 -> 0.2476 | G25: =Rēķini!M13 -> 11.66
A26: Apkure (patēriņš) 60% **** | D26: vienības | E26: 73.5 | F26: =Rekvizīti!C34 -> 0.0975 | G26: =Rēķini!N13 -> 7.17
A27: Siltummezgla apkalpošana | D27: m2 | E27: 47.1 | F27: =Rēķini!$O$2 -> 0.037 | G27: =Rēķini!$O$13 -> 1.74
A28: Apsaimniekošanas atlaide | G28: =Rēķini!Q13 -> -30.21
D29: Summa samaksai, EUR | G29: =SUM(G17:G28) -> 73.98
A31: =_xlfn.TEXTJOIN(" ",TRUE,"Summa vārdiem: ",Rēķini!U13) -> Summa vārdiem: Septiņdesmit trīs eiro, 98 centi
A34: =_xlfn.TEXTJOIN(" ",TRUE,"* Siltumenerģijas patēriņš", Rēķini!$D$30, "kopā: ",Rekvizīti!$C$19,"Mwh (",Rēķini!$E$32, "Eur)") -> * Siltumenerģijas patēriņš martā kopā: 7,81 Mwh ( 729,3 Eur)
